Workbook

Sheet Superficies y Valores
A1: Proforma Evaluación
A2: Superficies y valores
E3: 0.5 | F3: 0.5 | G3: 0.4 | H3: 0.6 | I3: 0.5 | N3: solo unidades | Q3: con 1 est + bod
A4: Tipología | B4: Cant | D4: m2 int | E4: m2 terr. | F4: m2 terr. azot. | G4: m2 bod. Habitable | H4: Uso y Goce | I4: m2 jardín | K4: m2 totales | L4: m2 calc. venta | N4: UF/m2 | O4: UF | Q4: UF/m2 | R4: UF
A5: Taller 1 | B5: 0 | D5: 0 | E5: 0 | F5: 0 | G5: 0 | H5: 0 | I5: 0 | K5: =SUM(D5:I5) -> 0 | L5: =D5+(E5*$E$3)+(F5*$F$3)+(G5*$G$3)+(H5*$H$3)+(I5*$I$3) -> 0 | N5: 75 | O5: =IF(B5=0,0,N5*L5) -> 0 | Q5: =IF(D5=0,0,R5/L5) -> 0 | R5: =IF(B5=0,0,O5+$B$31+$B$32) -> 0
A6: Taller 2 | B6: 0 | D6: 0 | E6: 0 | F6: 0 | G6: 0 | H6: 0 | I6: 0 | K6: =SUM(D6:I6) -> 0 | L6: =D6+(E6*$E$3)+(F6*$F$3)+(G6*$G$3)+(H6*$H$3)+(I6*$I$3) -> 0 | N6: 75 | O6: =IF(B6=0,0,N6*L6) -> 0 | Q6: =IF(D6=0,0,R6/L6) -> 0 | R6: =IF(B6=0,0,O6+$B$31+$B$32) -> 0
A7: Local 1 | B7: 1 | D7: 38 | E7: 0 | F7: 0 | G7: 0 | H7: 0 | I7: 0 | K7: =SUM(D7:I7) -> 38 | L7: =D7+(E7*$E$3)+(F7*$F$3)+(G7*$G$3)+(H7*$H$3)+(I7*$I$3) -> 38 | N7: 75 | O7: =IF(B7=0,0,N7*L7) -> 2850 | Q7: =IF(D7=0,0,R7/L7) -> 85.789474 | R7: =O7+$B$31+$B$32 -> 3260
A8: Sub Total Locales | B8: =SUM(B5:B7) -> 1 | D8: =SUM(D5:D7) -> 38 | E8: =SUM(E5:E7) -> 0 | F8: =SUM(F5:F7) -> 0 | G8: =SUM(G5:G7) -> 0 | H8: =SUM(H5:H7) -> 0 | I8: =SUM(I5:I7) -> 0 | K8: =SUMPRODUCT(K5:K7,B5:B7) -> 38 | L8: =SUM(L5:L7) -> 38 | N8: =SUMPRODUCT(N5:N7,B5:B7)/B8 -> 75 | O8: =SUMPRODUCT(O5:O7,B5:B7) -> 2850 | Q8: =SUMPRODUCT(Q5:Q7,B5:B7)/B8 -> 85.789474 | R8: =SUMPRODUCT(R5:R7,B5:B7) -> 3260
A10: Piso 2 - Tipo A | B10: 2 | D10: 68.2 | E10: 3.3 | F10: 0 | G10: 0 | H10: 0 | I10: 0 | K10: =SUM(D10:I10) -> 71.5 | L10: =D10+(E10*$E$3)+(F10*$F$3)+(G10*$G$3)+(H10*$H$3)+(I10*$I$3) -> 69.85 | N10: 65 | O10: =IF(B10=0,0,N10*L10) -> 4540.25 | Q10: =IF(D10=0,0,R10/L10) -> 70.869721 | R10: =O10+$B$31+$B$32 -> 4950.25
A11: Piso 2 - Tipo B | B11: 3 | D11: 61.1 | E11: 4.2 | F11: 0 | G11: 0 | H11: 0 | I11: 0 | K11: =SUM(D11:I11) -> 65.3 | L11: =D11+(E11*$E$3)+(F11*$F$3)+(G11*$G$3)+(H11*$H$3)+(I11*$I$3) -> 63.2 | N11: 65 | O11: =IF(B11=0,0,N11*L11) -> 4108 | Q11: =IF(D11=0,0,R11/L11) -> 71.487342 | R11: =O11+$B$31+$B$32 -> 4518
A12: Piso 3-5 - Tipo A | B12: 6 | D12: 69.8 | E12: 0 | F12: 0 | G12: 0 | H12: 0 | I12: 0 | K12: =SUM(D12:I12) -> 69.8 | L12: =D12+(E12*$E$3)+(F12*$F$3)+(G12*$G$3)+(H12*$H$3)+(I12*$I$3) -> 69.8 | N12: 65 | O12: =IF(B12=0,0,N12*L12) -> 4537 | Q12: =IF(D12=0,0,R12/L12) -> 70.873926 | R12: =O12+$B$31+$B$32 -> 4947
A13: Piso 3-5 - Tipo B | B13: 9 | D13: 63 | E13: 0 | F13: 0 | G13: 0 | H13: 0 | I13: 0 | K13: =SUM(D13:I13) -> 63 | L13: =D13+(E13*$E$3)+(F13*$F$3)+(G13*$G$3)+(H13*$H$3)+(I13*$I$3) -> 63 | N13: 65 | O13: =IF(B13=0,0,N13*L13) -> 4095 | Q13: =IF(D13=0,0,R13/L13) -> 71.507937 | R13: =O13+$B$31+$B$32 -> 4505
A14: Piso xxx | B14: 0 | D14: 0 | E14: 0 | F14: 0 | G14: 0 | H14: 0 | I14: 0 | K14: =SUM(D14:I14) -> 0 | L14: =D14+(E14*$E$3)+(F14*$F$3)+(G14*$G$3)+(H14*$H$3)+(I14*$I$3) -> 0 | N14: 0 | O14: =IF(B14=0,0,N14*L14) -> 0 | Q14: =IF(D14=0,0,R14/L14) -> 0 | R14: =IF(B14=0,0,Q14*L14) -> 0
A15: Piso xxx | B15: 0 | D15: 0 | E15: 0 | F15: 0 | G15: 0 | H15: 0 | I15: 0 | K15: =SUM(D15:I15) -> 0 | L15: =D15+(E15*$E$3)+(F15*$F$3)+(G15*$G$3)+(H15*$H$3)+(I15*$I$3) -> 0 | N15: 0 | O15: =IF(B15=0,0,N15*L15) -> 0 | Q15: =IF(D15=0,0,R15/L15) -> 0 | R15: =IF(B15=0,0,Q15*L15) -> 0
A16: Piso xxx | B16: 0 | D16: 0 | E16: 0 | F16: 0 | G16: 0 | H16: 0 | I16: 0 | K16: =SUM(D16:I16) -> 0 | L16: =D16+(E16*$E$3)+(F16*$F$3)+(G16*$G$3)+(H16*$H$3)+(I16*$I$3) -> 0 | N16: 0 | O16: =IF(B16=0,0,N16*L16) -> 0 | Q16: =IF(D16=0,0,R16/L16) -> 0 | R16: =IF(B16=0,0,Q16*L16) -> 0
A17: Piso xxx | B17: 0 | D17: 0 | E17: 0 | F17: 0 | G17: 0 | H17: 0 | I17: 0 | K17: =SUM(D17:I17) -> 0 | L17: =D17+(E17*$E$3)+(F17*$F$3)+(G17*$G$3)+(H17*$H$3)+(I17*$I$3) -> 0 | N17: 0 | O17: =IF(B17=0,0,N17*L17) -> 0 | Q17: =IF(D17=0,0,R17/L17) -> 0 | R17: =IF(B17=0,0,Q17*L17) -> 0
A18: Piso xxx | B18: 0 | D18: 0 | E18: 0 | F18: 0 | G18: 0 | H18: 0 | I18: 0 | K18: =SUM(D18:I18) -> 0 | L18: =D18+(E18*$E$3)+(F18*$F$3)+(G18*$G$3)+(H18*$H$3)+(I18*$I$3) -> 0 | N18: 0 | O18: =IF(B18=0,0,N18*L18) -> 0 | Q18: =IF(D18=0,0,R18/L18) -> 0 | R18: =IF(B18=0,0,Q18*L18) -> 0
A19: Azotea libre | B19: 0 | D19: 0 | E19: 0 | F19: 0 | G19: 0 | H19: 0 | I19: 0 | K19: =SUM(D19:I19) -> 0 | L19: =D19+(E19*$E$3)+(F19*$F$3)+(G19*$G$3)+(H19*$H$3)+(I19*$I$3) -> 0 | N19: 0 | O19: =IF(B19=0,0,N19*L19) -> 0 | Q19: =IF(D19=0,0,R19/L19) -> 0 | R19: =IF(B19=0,0,Q19*L19) -> 0
A20: Sub Total Departamentos | B20: =SUM(B10:B19) -> 20 | D20: =SUMPRODUCT(D10:D19,B10:B19) -> 1305.5 | E20: =SUMPRODUCT(E10:E19,B10:B19) -> 19.2 | F20: =SUMPRODUCT(F10:F19,B10:B19) -> 0 | G20: =SUMPRODUCT(G10:G19,B10:B19) -> 0 | H20: =SUMPRODUCT(H10:H19,B10:B19) -> 0 | I20: =SUMPRODUCT(I10:I19,B10:B19) -> 0 | K20: =SUMPRODUCT(K10:K19,B10:B19) -> 1324.7 | L20: =SUMPRODUCT(L10:L19,B10:B19) -> 1315.1 | N20: =SUMPRODUCT(N10:N19,B10:B19)/B20 -> 65 | O20: =SUMPRODUCT(O10:O19,B10:B19) -> 85481.5 | Q20: =SUMPRODUCT(Q10:Q19,B10:B19)/B20 -> 71.250822 | R20: =SUMPRODUCT(R10:R19,B10:B19) -> 93681.5
A22: Total | B22: =B8+B20 -> 21 | D22: =D8+D20 -> 1343.5 | E22: =E8+E20 -> 19.2 | F22: =F8+F20 -> 0 | G22: =G8+G20 -> 0 | H22: =H8+H20 -> 0 | I22: =I8+I20 -> 0 | K22: =K8+K20 -> 1362.7 | L22: =L8+L20 -> 1353.1 | O22: =O8+O20 -> 88331.5 | R22: =R8+R20 -> 96941.5
A23: Promedio | D23: =IF(B22=0,0,D22/B22) -> 63.97619 | E23: =IF(B22=0,0,E22/B22) -> 0.91428571 | K23: =IF(B22=0,0,K22/B22) -> 64.890476 | L23: =IF(B22=0,0,L22/B22) -> 64.433333 | O23: =IF(B22=0,0,O22/B22) -> 4206.2619 | R23: =IF(B22=0,0,R22/B22) -> 4616.2619
A25: Superficie Acceso Edificio | K25: =69-38 -> 31
A26: Superficie Estacionamientos Primer Piso | K26: 131
A27: Superficie Bodegas / Salas Servicio Primer Piso | K27: 4
A28: Superficie Circulaciones | K28: =66*4+70-K25+7 -> 310
A29: Total | K29: =K22+K25+K28 -> 1703.7
A31: Precio Unitario Estacionamiento | B31: 330
A32: Precio Unitario Bodega | B32: 80 | X32: =17+22+30+30+32 -> 131
A34: Leyenda:
A35: Input (editable)
A36: Fórmula (calculada)
A37: Referencia cruzada (otra hoja)
A38: Nota: J21 (Total m2 venta) alimenta Detalle Costos

Sheet Detalle Costos
A1: Detalle Costos
D2: Ingresos Totales (UF) → | E2: ='Superficies y Valores'!R22 -> 96941.5 | F2: m2 útil total → | G2: ='Superficies y Valores'!L22 -> 1353.1
A3: Ítem | B3: Sub-ítem | C3: m2 | D3: UF/m2 | E3: UF | F3: % total ventas | G3: % total costos | H3: UF/m2 útil
A4: Terreno | C4: 1000 | D4: =IF(C4=0,0,E4/C4) -> 11.9195 | E4: =SUM(E5:E7) -> 11919.5 | F4: =IF($E$2=0,0,E4/$E$2) -> 0.1229556 | G4: =IF(E70=0,0,E4/E70) -> 0.13089458 | H4: =IF($G$2=0,0,E4/$G$2) -> 8.8090311
B5: Lote 1 | C5: 1000 | D5: 11 | E5: =C5*D5 -> 11000 | F5: =IF($E$2=0,0,E5/$E$2) -> 0.1134705 | G5: =IF(E70=0,0,E5/E70) -> 0.12079705 | H5: =IF($G$2=0,0,E5/$G$2) -> 8.1294805
B6: Demolición | C6: 1000 | D6: 0.65 | E6: =C6*D6 -> 650 | F6: =IF($E$2=0,0,E6/$E$2) -> 0.0067050747 | G6: =IF(E70=0,0,E6/E70) -> 0.0071380074 | H6: =IF($G$2=0,0,E6/$G$2) -> 0.48037839
A7: 0.0245 | B7: Corretaje / Estructuración | D7: 0.26 | E7: =E5*A7 -> 269.5 | F7: =IF($E$2=0,0,E7/$E$2) -> 0.0027800271 | G7: =IF(E70=0,0,E7/E70) -> 0.0029595277 | H7: =IF($G$2=0,0,E7/$G$2) -> 0.19917227
A8: Construcción con IVA | C8: =C11 -> 1838.7 | D8: =IF(C8=0,0,E8/C8) -> 33.962278 | E8: =E10+E9 -> 62446.44 | F8: =IF($E$2=0,0,E8/$E$2) -> 0.64416622 | G8: =IF(E70=0,0,E8/E70) -> 0.68575869 | H8: =IF($G$2=0,0,E8/$G$2) -> 46.150647
A9: 0.19 | B9: IVA Construcción | C9: =C8 -> 1838.7 | D9: 4.79 | E9: =E10*A9 -> 9970.44 | F9: =IF($E$2=0,0,E9/$E$2) -> 0.10285007 | G9: =IF(E70=0,0,E9/E70) -> 0.10949088 | H9: =IF($G$2=0,0,E9/$G$2) -> 7.3685906
A10: Construcción sin IVA | C10: =C8 -> 1838.7 | D10: =IF(C10=0,0,E10/C10) -> 28.539729 | E10: =E12+E18+E22+E28+E38 -> 52476 | F10: =IF($E$2=0,0,E10/$E$2) -> 0.54131615 | G10: =IF(E70=0,0,E10/E70) -> 0.57626781 | H10: =IF($G$2=0,0,E10/$G$2) -> 38.782056
B11: (incluye techada exterior) | C11: =C12+C18+C22+C31+C35 -> 1838.7 | E11: =E12+E18+E22+E31+E35 -> 46326 | F11: =F12+F18+F22+F31+F35 -> 0.47787583 | G11: =G12+G18+G22+G31+G35 -> 0.50873128 | H11: =H12+H18+H22+H31+H35 -> 34.236937
B12: Departamentos | C12: =SUM(C13:C17) -> 1362.7 | E12: =SUM(E13:E17) -> 37696 | F12: =SUM(F13:F17) -> 0.38885307 | G12: =SUM(G13:G17) -> 0.4139605 | H12: =SUM(H13:H17) -> 27.85899
B13: Interior Departamentos | C13: ='Superficies y Valores'!D20 -> 1305.5 | D13: 28 | E13: =C13*D13 -> 36554 | F13: =IF($E$2=0,0,E13/$E$2) -> 0.37707277 | G13: =IF($E$70=0,0,E13/$E$70) -> 0.40141957 | H13: =IF($G$2=0,0,E13/$G$2) -> 27.015003
B14: Uso y Goce | C14: ='Superficies y Valores'!H22 -> 0 | D14: 0 | E14: =C14*D14 -> 0 | F14: =IF($E$2=0,0,E14/$E$2) -> 0 | G14: =IF($E$70=0,0,E14/$E$70) -> 0 | H14: =IF($G$2=0,0,E14/$G$2) -> 0
B15: Interior Locales Comerciales | C15: ='Superficies y Valores'!D8 -> 38 | D15: 25 | E15: =C15*D15 -> 950 | F15: =IF($E$2=0,0,E15/$E$2) -> 0.0097997246 | G15: =IF($E$70=0,0,E15/$E$70) -> 0.010432472 | H15: =IF($G$2=0,0,E15/$G$2) -> 0.70209149
B16: Terraza | C16: ='Superficies y Valores'!E20 -> 19.2 | D16: 10 | E16: =C16*D16 -> 192 | F16: =IF($E$2=0,0,E16/$E$2) -> 0.0019805759 | G16: =IF($E$70=0,0,E16/$E$70) -> 0.0021084576 | H16: =IF($G$2=0,0,E16/$G$2) -> 0.14189639
B17: Bodega habitable | C17: ='Superficies y Valores'!G20 -> 0 | D17: 0 | E17: =C17*D17 -> 0 | F17: =IF($E$2=0,0,E17/$E$2) -> 0 | G17: =IF($E$70=0,0,E17/$E$70) -> 0 | H17: =IF($G$2=0,0,E17/$G$2) -> 0
B18: Subterraneos | C18: =SUM(C19:C21) -> 0 | E18: =SUM(E19:E21) -> 0 | F18: =SUM(F19:F21) -> 0 | G18: =SUM(G19:G21) -> 0 | H18: =SUM(H19:H21) -> 0
B19: Estacionamientos | C19: 0 | D19: 14 | E19: =C19*D19 -> 0 | F19: =IF($E$2=0,0,E19/$E$2) -> 0 | G19: =IF($E$70=0,0,E19/$E$70) -> 0 | H19: =IF($G$2=0,0,E19/$G$2) -> 0
B20: Bodegas | C20: 0 | D20: 14 | E20: =C20*D20 -> 0 | F20: =IF($E$2=0,0,E20/$E$2) -> 0 | G20: =IF($E$70=0,0,E20/$E$70) -> 0 | H20: =IF($G$2=0,0,E20/$G$2) -> 0
B21: Otras Superficies Comunes | C21: 0 | D21: 24 | E21: =C21*D21 -> 0 | F21: =IF($E$2=0,0,E21/$E$2) -> 0 | G21: =IF($E$70=0,0,E21/$E$70) -> 0 | H21: =IF($G$2=0,0,E21/$G$2) -> 0
B22: Superficies Comunes | C22: =SUM(C23:C27) -> 345 | E22: =SUM(E23:E27) -> 8368 | F22: =SUM(F23:F27) -> 0.0863201 | G22: =SUM(G23:G27) -> 0.091893609 | H22: =SUM(H23:H27) -> 6.1843175
B23: Circulaciones | C23: ='Superficies y Valores'!K28 -> 310 | D23: 24 | E23: =C23*D23 -> 7440 | F23: =IF($E$2=0,0,E23/$E$2) -> 0.076747317 | G23: =IF($E$70=0,0,E23/$E$70) -> 0.081702731 | H23: =IF($G$2=0,0,E23/$G$2) -> 5.498485
B24: Superficie ascensores | C24: 0 | D24: 24 | E24: =C24*D24 -> 0 | F24: =IF($E$2=0,0,E24/$E$2) -> 0 | G24: =IF($E$70=0,0,E24/$E$70) -> 0 | H24: =IF($G$2=0,0,E24/$G$2) -> 0
B25: Superficie acceso edificio | C25: ='Superficies y Valores'!K25 -> 31 | D25: 28 | E25: =C25*D25 -> 868 | F25: =IF($E$2=0,0,E25/$E$2) -> 0.0089538536 | G25: =IF($E$70=0,0,E25/$E$70) -> 0.0095319853 | H25: =IF($G$2=0,0,E25/$G$2) -> 0.64148991
B26: Azotea comun | C26: 0 | D26: 24 | E26: =C26*D26 -> 0 | F26: =IF($E$2=0,0,E26/$E$2) -> 0 | G26: =IF($E$70=0,0,E26/$E$70) -> 0 | H26: =IF($G$2=0,0,E26/$G$2) -> 0
B27: Bodegas Primer Piso | C27: ='Superficies y Valores'!K27 -> 4 | D27: 15 | E27: =C27*D27 -> 60 | F27: =IF($E$2=0,0,E27/$E$2) -> 0.00061892997 | G27: =IF($E$70=0,0,E27/$E$70) -> 0.00065889299 | H27: =IF($G$2=0,0,E27/$G$2) -> 0.044342621
B28: Tratamiento Superficies Exteriores | C28: =SUM(C29:C37) -> 1631 | E28: =SUM(E29:E37) -> 6012 | F28: =SUM(F29:F37) -> 0.062016783 | G28: =SUM(G29:G37) -> 0.066021078 | H28: =SUM(H29:H37) -> 4.4431306
B29: Urbanización | C29: =C5 -> 1000 | D29: 0 | E29: =C29*D29 -> 0 | F29: =IF($E$2=0,0,E29/$E$2) -> 0 | G29: =IF($E$70=0,0,E29/$E$70) -> 0 | H29: =IF($G$2=0,0,E29/$G$2) -> 0
B30: Urbanización Área Afecta | C30: 0 | D30: 2 | E30: =C30*D30 -> 0 | F30: =IF($E$2=0,0,E30/$E$2) -> 0 | G30: =IF($E$70=0,0,E30/$E$70) -> 0 | H30: =IF($G$2=0,0,E30/$G$2) -> 0
B31: Estacionamientos Primer Piso | C31: ='Superficies y Valores'!K26 -> 131 | D31: 2 | E31: =C31*D31 -> 262 | F31: =IF($E$2=0,0,E31/$E$2) -> 0.0027026609 | G31: =IF($E$70=0,0,E31/$E$70) -> 0.0028771661 | H31: =IF($G$2=0,0,E31/$G$2) -> 0.19362944
B32: Paisajismo comunes | C32: 100 | D32: 1.5 | E32: =C32*D32 -> 150 | F32: =IF($E$2=0,0,E32/$E$2) -> 0.0015473249 | G32: =IF($E$70=0,0,E32/$E$70) -> 0.0016472325 | H32: =IF($G$2=0,0,E32/$G$2) -> 0.11085655
B33: Paisajismo jardines privados | C33: 0 | D33: 1 | E33: =C33*D33 -> 0 | F33: =IF($E$2=0,0,E33/$E$2) -> 0 | G33: =IF($E$70=0,0,E33/$E$70) -> 0 | H33: =IF($G$2=0,0,E33/$G$2) -> 0
B34: Paisajismo con techo | C34: 400 | D34: 14 | E34: =C34*D34 -> 5600 | F34: =IF($E$2=0,0,E34/$E$2) -> 0.057766798 | G34: =IF($E$70=0,0,E34/$E$70) -> 0.061496679 | H34: =IF($G$2=0,0,E34/$G$2) -> 4.1386446
B35: Circulación Est. Primer Piso | C35: 0 | D35: 2 | E35: =C35*D35 -> 0 | F35: =IF($E$2=0,0,E35/$E$2) -> 0 | G35: =IF($E$70=0,0,E35/$E$70) -> 0 | H35: =IF($G$2=0,0,E35/$G$2) -> 0
B36: Terraza Azotea Comun | C36: 0 | D36: 5 | E36: =C36*D36 -> 0 | F36: =IF($E$2=0,0,E36/$E$2) -> 0 | G36: =IF($E$70=0,0,E36/$E$70) -> 0 | H36: =IF($G$2=0,0,E36/$G$2) -> 0
B37: Terrazas Azotea Departamentos | C37: 0 | D37: 5 | E37: =C37*D37 -> 0 | F37: =IF($E$2=0,0,E37/$E$2) -> 0 | G37: =IF($E$70=0,0,E37/$E$70) -> 0 | H37: =IF($G$2=0,0,E37/$G$2) -> 0
B38: Obras Complementarias | C38: =SUM(C39:C45) -> 200 | E38: =SUM(E39:E45) -> 400 | F38: =IF($E$2=0,0,E38/$E$2) -> 0.0041261998 | G38: =SUM(G39:G45) -> 0.0043926199 | H38: =SUM(H39:H45) -> 0.29561747
B39: Cierre Perimetral | C39: 200 | D39: 2 | E39: =C39*D39 -> 400 | F39: =IF($E$2=0,0,E39/$E$2) -> 0.0041261998 | G39: =IF($E$70=0,0,E39/$E$70) -> 0.0043926199 | H39: =IF($G$2=0,0,E39/$G$2) -> 0.29561747
B40: Sala Común | C40: 0 | D40: 500 | E40: 0 | F40: =IF($E$2=0,0,E40/$E$2) -> 0 | G40: =IF($E$70=0,0,E40/$E$70) -> 0 | H40: =IF($G$2=0,0,E40/$G$2) -> 0
...

Sheet Resultados
A1: Resultados
A2: Vinculado: Ingresos ← Superficies | Costos ← Detalle Costos
A3: Resultados
A4: RESULTADOS
D5: UF
A6: Ingresos | D6: ='Superficies y Valores'!R22 -> 96941.5
A7: Costo | B7: Proyecto Puro | D7: ='Detalle Costos'!E68 -> 87728.158
B8: Proyecto Financiado | D8: ='Detalle Costos'!E70 -> 91061.828
A10: Capital | B10: Requerido Flujo | C10: 0.2 | D10: =D7*C10 -> 17545.632
B11: Requerido s/terreno | C11: 0.7 | D11: =C11*'Detalle Costos'!E4 -> 8343.65
A13: Margen | B13: UF | D13: =D6-D8 -> 5879.6722
B14: % Ventas | D14: =IF(D6=0,0,D13/D6) -> 0.060651756
B15: % Costo Total | D15: =IF(D8=0,0,D13/D8) -> 0.064567914
B16: % Capital Flujo | D16: =(D10+D11)/D13 -> 4.4031845
A18: TIR | B18: Proyecto Puro | D18: ='VAN _ TIR'!G11 -> 0.13682299
B19: Proyecto Financiado | D19: ='VAN _ TIR'!G12 -> 0.087861618
A21: Leyenda:
A22: Input (editable)
A23: Fórmula (calculada)
A24: Referencia cruzada (otra hoja)
A25: Nota: Esc2 recalcula ingresos y costos ajustando por ratio de precio UF/m2
A26: Nota: Capital y TIR son inputs manuales (provienen del modelo de flujo de caja)

Sheet VAN _ TIR
A1: VAN y TIR — Análisis de Rentabilidad
A2: Modelo de Flujos de Caja Mensual
A3: PARÁMETROS DE EVALUACIÓN | E3: RESULTADOS
A4: Tasa de descuento mensual (input) | C4: 0.01
A5: Tasa de descuento anual equivalente | C5: =(1+C4)^12-1 -> 0.12682503 | E5: VAN Proyecto Puro (UF) | G5: =K35+NPV(C4,K36:K58) -> 566.20065
A6: Período de análisis (meses) | C6: 24 | E6: VAN Proyecto Financiado (UF) | G6: =N35+NPV(C4,N36:N58) -> -2193.2111
A7: Duración de construcción (meses) | C7: 18
A8: Mes de inicio de pre-ventas (input) | C8: 3 | E8: TIR mensual Proyecto Puro | G8: =IRR(K35:K58) -> 0.010743764
A9: Mes de entrega — recepción final (input) | C9: 19 | E9: TIR mensual Proyecto Financiado | G9: =IRR(N35:N58) -> 0.007042512
A10: % Ingresos cobrados en pre-venta (input) | C10: 0.2
A11: Mes inicio — Proyectos, Permisos y Empalmes (input) | C11: 0 | E11: TIR anual Proyecto Puro | G11: =(1+IRR(K35:K58))^12-1 -> 0.13682299
A12: Mes término — Proyectos, Permisos y Empalmes (input) | C12: 4 | E12: TIR anual Proyecto Financiado | G12: =(1+IRR(N35:N58))^12-1 -> 0.087861618
A14: DATOS DEL PROYECTO (referencias a otras hojas) | E14: Nota: Los valores de TIR anual calculados arriba actualizan automáticamente las celdas D18 y D19 de la hoja "Resultados".
A15: Ingresos Totales | B15: UF | C15: ='Superficies y Valores'!R22 -> 96941.5
A16: Costo Terreno | B16: UF | C16: ='Detalle Costos'!E4 -> 11919.5
A17: Costo Construcción sin IVA | B17: UF | C17: ='Detalle Costos'!E10 -> 52476
A18: Costos Proyectos, Permisos y Empalmes | B18: UF | C18: ='Detalle Costos'!E46 -> 7869.004
A19: Costos Adm., Gestión y Ventas | B19: UF | C19: ='Detalle Costos'!E55 -> 12497.001
A20: Costo Financiero | B20: UF | C20: ='Detalle Costos'!E67 -> 2966.6527
A21: IVA a Pagar | B21: UF | C21: ='Detalle Costos'!E69 -> 3333.67
A22: Costo Total Proyecto Puro (sin IVA a pagar) | B22: UF | C22: ='Detalle Costos'!E68 -> 87728.158
A23: Costo Total Proyecto Financiado (con IVA a pagar) | B23: UF | C23: ='Detalle Costos'!E70 -> 91061.828
A25: SUPUESTOS DE DISTRIBUCIÓN TEMPORAL
A26: • Terreno: 100 % en el mes 0
A27: • Construcción sin IVA: distribuido uniformemente en los meses 1 a C7
A28: • Proyectos, Permisos y Empalmes: distribuido uniformemente en los meses C11 a C12 (ajustable)
A29: • Adm., Gestión y Ventas: distribuido uniformemente desde el mes C8 hasta el mes C9
A30: • Costo Financiero e IVA a Pagar: íntegramente en el mes de entrega (C9)
A31: • Ingresos Pre-venta (C10 = 30 %): distribuidos uniformemente desde el mes C8 hasta el mes C9-1
A32: • Ingresos de Entrega (1-C10 = 70 %): íntegramente en el mes de entrega (C9)
A33: TABLA DE FLUJOS DE CAJA (montos en UF)
A34: Mes | B34: Ing. Pre-venta | C34: Ing. Entrega | D34: Total Ingresos | E34: Terreno | F34: Construcción | G34: Proy. y Permisos | H34: Adm. y Ventas | I34: Costo Financiero | J34: Total Egresos Puro | K34: Flujo Neto Puro | L34: IVA a Pagar | M34: Total Egresos Financiado | N34: Flujo Neto Financiado
A35: 0 | B35: =IF(AND($A35>=$C$8,$A35<=$C$9-1),$C$15*$C$10/($C$9-$C$8),0) -> 0 | C35: =IF($A35=$C$9,$C$15*(1-$C$10),0) -> 0 | D35: =B35+C35 -> 0 | E35: =IF($A35=0,$C$16,0) -> 11919.5 | F35: =IF(AND($A35>=1,$A35<=$C$7),$C$17/$C$7,0) -> 0 | G35: =IF(AND($A35>=$C$11,$A35<=$C$12),$C$18/($C$12-$C$11+1),0) -> 1573.8008 | H35: =IF(AND($A35>=$C$8,$A35<=$C$9),$C$19/($C$9-$C$8+1),0) -> 0 | I35: =IF($A35=$C$9,$C$20,0) -> 0 | J35: =E35+F35+G35+H35+I35 -> 13493.301 | K35: =D35-J35 -> -13493.301 | L35: =IF($A35=$C$9,$C$21,0) -> 0 | M35: =J35+L35 -> 13493.301 | N35: =D35-M35 -> -13493.301
A36: 1 | B36: =IF(AND($A36>=$C$8,$A36<=$C$9-1),$C$15*$C$10/($C$9-$C$8),0) -> 0 | C36: =IF($A36=$C$9,$C$15*(1-$C$10),0) -> 0 | D36: =B36+C36 -> 0 | E36: =IF($A36=0,$C$16,0) -> 0 | F36: =IF(AND($A36>=1,$A36<=$C$7),$C$17/$C$7,0) -> 2915.3333 | G36: =IF(AND($A36>=$C$11,$A36<=$C$12),$C$18/($C$12-$C$11+1),0) -> 1573.8008 | H36: =IF(AND($A36>=$C$8,$A36<=$C$9),$C$19/($C$9-$C$8+1),0) -> 0 | I36: =IF($A36=$C$9,$C$20,0) -> 0 | J36: =E36+F36+G36+H36+I36 -> 4489.1341 | K36: =D36-J36 -> -4489.1341 | L36: =IF($A36=$C$9,$C$21,0) -> 0 | M36: =J36+L36 -> 4489.1341 | N36: =D36-M36 -> -4489.1341
A37: 2 | B37: =IF(AND($A37>=$C$8,$A37<=$C$9-1),$C$15*$C$10/($C$9-$C$8),0) -> 0 | C37: =IF($A37=$C$9,$C$15*(1-$C$10),0) -> 0 | D37: =B37+C37 -> 0 | E37: =IF($A37=0,$C$16,0) -> 0 | F37: =IF(AND($A37>=1,$A37<=$C$7),$C$17/$C$7,0) -> 2915.3333 | G37: =IF(AND($A37>=$C$11,$A37<=$C$12),$C$18/($C$12-$C$11+1),0) -> 1573.8008 | H37: =IF(AND($A37>=$C$8,$A37<=$C$9),$C$19/($C$9-$C$8+1),0) -> 0 | I37: =IF($A37=$C$9,$C$20,0) -> 0 | J37: =E37+F37+G37+H37+I37 -> 4489.1341 | K37: =D37-J37 -> -4489.1341 | L37: =IF($A37=$C$9,$C$21,0) -> 0 | M37: =J37+L37 -> 4489.1341 | N37: =D37-M37 -> -4489.1341
A38: 3 | B38: =IF(AND($A38>=$C$8,$A38<=$C$9-1),$C$15*$C$10/($C$9-$C$8),0) -> 1211.7687 | C38: =IF($A38=$C$9,$C$15*(1-$C$10),0) -> 0 | D38: =B38+C38 -> 1211.7687 | E38: =IF($A38=0,$C$16,0) -> 0 | F38: =IF(AND($A38>=1,$A38<=$C$7),$C$17/$C$7,0) -> 2915.3333 | G38: =IF(AND($A38>=$C$11,$A38<=$C$12),$C$18/($C$12-$C$11+1),0) -> 1573.8008 | H38: =IF(AND($A38>=$C$8,$A38<=$C$9),$C$19/($C$9-$C$8+1),0) -> 735.11771 | I38: =IF($A38=$C$9,$C$20,0) -> 0 | J38: =E38+F38+G38+H38+I38 -> 5224.2518 | K38: =D38-J38 -> -4012.4831 | L38: =IF($A38=$C$9,$C$21,0) -> 0 | M38: =J38+L38 -> 5224.2518 | N38: =D38-M38 -> -4012.4831
A39: 4 | B39: =IF(AND($A39>=$C$8,$A39<=$C$9-1),$C$15*$C$10/($C$9-$C$8),0) -> 1211.7687 | C39: =IF($A39=$C$9,$C$15*(1-$C$10),0) -> 0 | D39: =B39+C39 -> 1211.7687 | E39: =IF($A39=0,$C$16,0) -> 0 | F39: =IF(AND($A39>=1,$A39<=$C$7),$C$17/$C$7,0) -> 2915.3333 | G39: =IF(AND($A39>=$C$11,$A39<=$C$12),$C$18/($C$12-$C$11+1),0) -> 1573.8008 | H39: =IF(AND($A39>=$C$8,$A39<=$C$9),$C$19/($C$9-$C$8+1),0) -> 735.11771 | I39: =IF($A39=$C$9,$C$20,0) -> 0 | J39: =E39+F39+G39+H39+I39 -> 5224.2518 | K39: =D39-J39 -> -4012.4831 | L39: =IF($A39=$C$9,$C$21,0) -> 0 | M39: =J39+L39 -> 5224.2518 | N39: =D39-M39 -> -4012.4831
A40: 5 | B40: =IF(AND($A40>=$C$8,$A40<=$C$9-1),$C$15*$C$10/($C$9-$C$8),0) -> 1211.7687 | C40: =IF($A40=$C$9,$C$15*(1-$C$10),0) -> 0 | D40: =B40+C40 -> 1211.7687 | E40: =IF($A40=0,$C$16,0) -> 0 | F40: =IF(AND($A40>=1,$A40<=$C$7),$C$17/$C$7,0) -> 2915.3333 | G40: =IF(AND($A40>=$C$11,$A40<=$C$12),$C$18/($C$12-$C$11+1),0) -> 0 | H40: =IF(AND($A40>=$C$8,$A40<=$C$9),$C$19/($C$9-$C$8+1),0) -> 735.11771 | I40: =IF($A40=$C$9,$C$20,0) -> 0 | J40: =E40+F40+G40+H40+I40 -> 3650.451 | K40: =D40-J40 -> -2438.6823 | L40: =IF($A40=$C$9,$C$21,0) -> 0 | M40: =J40+L40 -> 3650.451 | N40: =D40-M40 -> -2438.6823
A41: 6 | B41: =IF(AND($A41>=$C$8,$A41<=$C$9-1),$C$15*$C$10/($C$9-$C$8),0) -> 1211.7687 | C41: =IF($A41=$C$9,$C$15*(1-$C$10),0) -> 0 | D41: =B41+C41 -> 1211.7687 | E41: =IF($A41=0,$C$16,0) -> 0 | F41: =IF(AND($A41>=1,$A41<=$C$7),$C$17/$C$7,0) -> 2915.3333 | G41: =IF(AND($A41>=$C$11,$A41<=$C$12),$C$18/($C$12-$C$11+1),0) -> 0 | H41: =IF(AND($A41>=$C$8,$A41<=$C$9),$C$19/($C$9-$C$8+1),0) -> 735.11771 | I41: =IF($A41=$C$9,$C$20,0) -> 0 | J41: =E41+F41+G41+H41+I41 -> 3650.451 | K41: =D41-J41 -> -2438.6823 | L41: =IF($A41=$C$9,$C$21,0) -> 0 | M41: =J41+L41 -> 3650.451 | N41: =D41-M41 -> -2438.6823
A42: 7 | B42: =IF(AND($A42>=$C$8,$A42<=$C$9-1),$C$15*$C$10/($C$9-$C$8),0) -> 1211.7687 | C42: =IF($A42=$C$9,$C$15*(1-$C$10),0) -> 0 | D42: =B42+C42 -> 1211.7687 | E42: =IF($A42=0,$C$16,0) -> 0 | F42: =IF(AND($A42>=1,$A42<=$C$7),$C$17/$C$7,0) -> 2915.3333 | G42: =IF(AND($A42>=$C$11,$A42<=$C$12),$C$18/($C$12-$C$11+1),0) -> 0 | H42: =IF(AND($A42>=$C$8,$A42<=$C$9),$C$19/($C$9-$C$8+1),0) -> 735.11771 | I42: =IF($A42=$C$9,$C$20,0) -> 0 | J42: =E42+F42+G42+H42+I42 -> 3650.451 | K42: =D42-J42 -> -2438.6823 | L42: =IF($A42=$C$9,$C$21,0) -> 0 | M42: =J42+L42 -> 3650.451 | N42: =D42-M42 -> -2438.6823
...
