Workbook
Name n_familias: 'Parámetros'!$B$5
Name cuota_mensual: 'Parámetros'!$B$6
Name tasa_desercion: 'Parámetros'!$B$7
Name familias_sorteo: 'Parámetros'!$B$8
Name precio_terreno: 'Parámetros'!$B$10
Name sup_terreno: 'Parámetros'!$B$11
Name viv_x_terreno: 'Parámetros'!$B$12
Name apreciacion_suelo: 'Parámetros'!$B$13
Name cap2_monto: 'Parámetros'!$B$15
Name cap2_ratio: 'Parámetros'!$B$16
Name cap2_retorno: 'Parámetros'!$B$17
Name plazo_anos: 'Parámetros'!$B$18
Name gracia_meses: 'Parámetros'!$B$19
Name subsidio_uf: 'Parámetros'!$B$21
Name valor_uf: 'Parámetros'!$B$22
Name pct_subsidio: 'Parámetros'!$B$23
Name subsidio_destino: 'Parámetros'!$B$24
Name canon_mensual: 'Parámetros'!$B$26
Name canon_crecimiento: 'Parámetros'!$B$27
Name costo_construccion: 'Parámetros'!$B$29
Name tasa_credito: 'Parámetros'!$B$30
Name plazo_credito: 'Parámetros'!$B$31

Sheet Parámetros
A1: FONDO MUTUALISTA DE SUELO URBANO — Parámetros del Modelo
A2: Las celdas amarillas son editables. Todos los cálculos se actualizan automáticamente.
A3: Parámetro | B3: Valor | C3: Unidad | D3: Nota
A4: ▌ 1. DEMANDA
A5: Número de familias participantes | B5: 500 | C5: familias | D5: Base del fondo
A6: Cuota mensual por familia | B6: 30000 | C6: CLP/mes | D6: Aporte mensual
A7: Tasa de deserción anual estimada | B7: 0.05 | C7: anual | D7: 5% base ajustada
A8: Familias por grupo de sorteo | B8: 25 | C8: familias | D8: Tamaño lote
A9: ▌ 2. SUELO
A10: Precio promedio terreno objetivo | B10: 120000000 | C10: CLP | D10: Por terreno completo
A11: Superficie promedio terreno | B11: 1000 | C11: m² | D11: Referencial
A12: Viviendas por terreno | B12: 25 | C12: unidades | D12: Densidad
A13: Apreciación anual estimada del suelo | B13: 0.05 | C13: anual | D13: Inflación suelo
A14: ▌ 3. CAPITAL PACIENTE — CAPA 2
A15: Monto comprometido total | B15: 500000000 | C15: CLP | D15: Capital paciente total
A16: Ratio desembolso Capa 2 / Capa 1 | B16: 3 | C16: x | D16: Por cada 1 CLP de Capa 1, desembolsa X de Capa 2
A17: Retorno anual exigido Capa 2 | B17: 0.05 | C17: anual | D17: Costo capital
A18: Plazo del fondo | B18: 15 | C18: años | D18: Horizonte total
A19: Período de gracia Capa 2 | B19: 12 | C19: meses | D19: Sin interés inicial
A20: ▌ 4. SUBSIDIO ESTATAL — CAPA 3
A21: Subsidio por familia | B21: 800 | C21: UF/familia | D21: Componente suelo
A22: Valor UF | B22: 38000 | C22: CLP/UF | D22: Actualizar periódicamente
A23: % familias que acceden a subsidio | B23: 0.6 | C23: % | D23: Cobertura estimada
A24: Destino del subsidio | B24: 1 | C24: % | D24: 100% a suelo CLT
A25: ▌ 5. CANON DE USO DE SUELO (GROUND LEASE)
A26: Canon mensual por familia en CLT | B26: 25000 | C26: CLP/mes | D26: Arrendamiento suelo
A27: Crecimiento anual del canon (IPC) | B27: 0.03 | C27: anual | D27: Indexación IPC
A28: ▌ 6. CONSTRUCCIÓN (referencial — no parte del fondo de suelo)
A29: Costo construcción por vivienda | B29: 1200 | C29: UF/vivienda | D29: Referencial mercado
A30: Tasa crédito bancario construcción | B30: 0.04 | C30: anual | D30: Tasa referencial
A31: Plazo crédito bancario | B31: 20 | C31: años | D31: Referencial
A32: ▌ 7. CELDAS AUXILIARES (usadas por tablas de sensibilidad)
A33: Input variable cuota (Tabla 1) | B33: =B5 | C33: CLP | D33: Variable de entrada para Tabla Sensibilidad 1
A34: Input variable familias (Tabla 1 y 3) | B34: =B4 | C34: familias | D34: Variable de entrada para Tabla Sensibilidad 1 y 3
A35: Input variable canon (Tabla 2) | B35: =B17 | C35: CLP | D35: Variable de entrada para Tabla Sensibilidad 2
A36: Input variable precio terreno (Tabla 3) | B36: =B8 | C36: CLP | D36: Variable de entrada para Tabla Sensibilidad 3

Sheet Flujo del Fondo
A1: FLUJO DEL FONDO — Horizonte 180 Meses (15 Años)
A2: Mes | B2: Año | C2: Fam. Activas | D2: Ap. Capa 1 | E2: Acum. Capa 1 | F2: Desemb. C2 | G2: Acum. C2 | H2: Acum. C3 | I2: Cap. Total | J2: Terrenos | K2: Fam. Ubic. | L2: En Espera | M2: Canon Mes. | N2: Acum. Canon | O2: Serv. C2 | P2: Flujo Neto | Q2: Acum. Neto
A3: Mes | B3: Año | C3: Familias Activas | D3: Aporte Mensual Capa 1 (CLP) | E3: Acumulado Capa 1 (CLP) | F3: Desembolso Capa 2 Mensual (CLP) | G3: Capital Capa 2 Acumulado (CLP) | H3: Subsidio Capa 3 Acumulado (CLP) | I3: Capital Total Disponible (CLP) | J3: Terrenos Adquiridos Acumulados | K3: Familias Ubicadas Acumuladas | L3: Familias en Espera | M3: Canon Mensual Recibido (CLP) | N3: Canon Acumulado (CLP) | O3: Servicio Deuda Capa 2 Mensual (CLP) | P3: Flujo Neto Mensual (CLP) | Q3: Flujo Neto Acumulado (CLP)
A4: 1 | B4: =INT((1-1)/12)+1 | C4: ='Parámetros'!$B$5 | D4: =C4*'Parámetros'!$B$6 | E4: =D4 | F4: =MIN('Parámetros'!$B$15, D4*'Parámetros'!$B$16) | G4: =F4 | H4: =0 | I4: =E4+G4+H4 | J4: =ENTERO(I4/('Parámetros'!$B$10*(1+'Parámetros'!$B$13)^((1-1)/12))) | K4: =J4*'Parámetros'!$B$12 | L4: =MAX(0,C4-K4) | M4: =K4*('Parámetros'!$B$26*(1+'Parámetros'!$B$27)^((1-1)/12)) | N4: =M4 | O4: =IF(1<='Parámetros'!$B$19,0,G4*'Parámetros'!$B$17/12) | P4: =D4+M4-O4 | Q4: =P4
A5: 2 | B5: =INT((2-1)/12)+1 | C5: =REDONDEAR(C4*(1-'Parámetros'!$B$7)^(1/12),0) | D5: =C5*'Parámetros'!$B$6 | E5: =E4+D5 | F5: =MAX(0, MIN('Parámetros'!$B$15-G4, D5*'Parámetros'!$B$16)) | G5: =G4+F5 | H5: =H4+IF(J5>J4,(J5-J4)*('Parámetros'!$B$12*'Parámetros'!$B$23*'Parámetros'!$B$21*'Parámetros'!$B$22*'Parámetros'!$B$24),0) | I5: =E5+G5+H5 | J5: =ENTERO(I5/('Parámetros'!$B$10*(1+'Parámetros'!$B$13)^((2-1)/12))) | K5: =J5*'Parámetros'!$B$12 | L5: =MAX(0,C5-K5) | M5: =K5*('Parámetros'!$B$26*(1+'Parámetros'!$B$27)^((2-1)/12)) | N5: =N4+M5 | O5: =IF(2<='Parámetros'!$B$19,0,G5*'Parámetros'!$B$17/12) | P5: =D5+M5-O5 | Q5: =Q4+P5
A6: 3 | B6: =INT((3-1)/12)+1 | C6: =REDONDEAR(C5*(1-'Parámetros'!$B$7)^(1/12),0) | D6: =C6*'Parámetros'!$B$6 | E6: =E5+D6 | F6: =MAX(0, MIN('Parámetros'!$B$15-G5, D6*'Parámetros'!$B$16)) | G6: =G5+F6 | H6: =H5+IF(J6>J5,(J6-J5)*('Parámetros'!$B$12*'Parámetros'!$B$23*'Parámetros'!$B$21*'Parámetros'!$B$22*'Parámetros'!$B$24),0) | I6: =E6+G6+H6 | J6: =ENTERO(I6/('Parámetros'!$B$10*(1+'Parámetros'!$B$13)^((3-1)/12))) | K6: =J6*'Parámetros'!$B$12 | L6: =MAX(0,C6-K6) | M6: =K6*('Parámetros'!$B$26*(1+'Parámetros'!$B$27)^((3-1)/12)) | N6: =N5+M6 | O6: =IF(3<='Parámetros'!$B$19,0,G6*'Parámetros'!$B$17/12) | P6: =D6+M6-O6 | Q6: =Q5+P6
A7: 4 | B7: =INT((4-1)/12)+1 | C7: =REDONDEAR(C6*(1-'Parámetros'!$B$7)^(1/12),0) | D7: =C7*'Parámetros'!$B$6 | E7: =E6+D7 | F7: =MAX(0, MIN('Parámetros'!$B$15-G6, D7*'Parámetros'!$B$16)) | G7: =G6+F7 | H7: =H6+IF(J7>J6,(J7-J6)*('Parámetros'!$B$12*'Parámetros'!$B$23*'Parámetros'!$B$21*'Parámetros'!$B$22*'Parámetros'!$B$24),0) | I7: =E7+G7+H7 | J7: =ENTERO(I7/('Parámetros'!$B$10*(1+'Parámetros'!$B$13)^((4-1)/12))) | K7: =J7*'Parámetros'!$B$12 | L7: =MAX(0,C7-K7) | M7: =K7*('Parámetros'!$B$26*(1+'Parámetros'!$B$27)^((4-1)/12)) | N7: =N6+M7 | O7: =IF(4<='Parámetros'!$B$19,0,G7*'Parámetros'!$B$17/12) | P7: =D7+M7-O7 | Q7: =Q6+P7
A8: 5 | B8: =INT((5-1)/12)+1 | C8: =REDONDEAR(C7*(1-'Parámetros'!$B$7)^(1/12),0) | D8: =C8*'Parámetros'!$B$6 | E8: =E7+D8 | F8: =MAX(0, MIN('Parámetros'!$B$15-G7, D8*'Parámetros'!$B$16)) | G8: =G7+F8 | H8: =H7+IF(J8>J7,(J8-J7)*('Parámetros'!$B$12*'Parámetros'!$B$23*'Parámetros'!$B$21*'Parámetros'!$B$22*'Parámetros'!$B$24),0) | I8: =E8+G8+H8 | J8: =ENTERO(I8/('Parámetros'!$B$10*(1+'Parámetros'!$B$13)^((5-1)/12))) | K8: =J8*'Parámetros'!$B$12 | L8: =MAX(0,C8-K8) | M8: =K8*('Parámetros'!$B$26*(1+'Parámetros'!$B$27)^((5-1)/12)) | N8: =N7+M8 | O8: =IF(5<='Parámetros'!$B$19,0,G8*'Parámetros'!$B$17/12) | P8: =D8+M8-O8 | Q8: =Q7+P8
A9: 6 | B9: =INT((6-1)/12)+1 | C9: =REDONDEAR(C8*(1-'Parámetros'!$B$7)^(1/12),0) | D9: =C9*'Parámetros'!$B$6 | E9: =E8+D9 | F9: =MAX(0, MIN('Parámetros'!$B$15-G8, D9*'Parámetros'!$B$16)) | G9: =G8+F9 | H9: =H8+IF(J9>J8,(J9-J8)*('Parámetros'!$B$12*'Parámetros'!$B$23*'Parámetros'!$B$21*'Parámetros'!$B$22*'Parámetros'!$B$24),0) | I9: =E9+G9+H9 | J9: =ENTERO(I9/('Parámetros'!$B$10*(1+'Parámetros'!$B$13)^((6-1)/12))) | K9: =J9*'Parámetros'!$B$12 | L9: =MAX(0,C9-K9) | M9: =K9*('Parámetros'!$B$26*(1+'Parámetros'!$B$27)^((6-1)/12)) | N9: =N8+M9 | O9: =IF(6<='Parámetros'!$B$19,0,G9*'Parámetros'!$B$17/12) | P9: =D9+M9-O9 | Q9: =Q8+P9
A10: 7 | B10: =INT((7-1)/12)+1 | C10: =REDONDEAR(C9*(1-'Parámetros'!$B$7)^(1/12),0) | D10: =C10*'Parámetros'!$B$6 | E10: =E9+D10 | F10: =MAX(0, MIN('Parámetros'!$B$15-G9, D10*'Parámetros'!$B$16)) | G10: =G9+F10 | H10: =H9+IF(J10>J9,(J10-J9)*('Parámetros'!$B$12*'Parámetros'!$B$23*'Parámetros'!$B$21*'Parámetros'!$B$22*'Parámetros'!$B$24),0) | I10: =E10+G10+H10 | J10: =ENTERO(I10/('Parámetros'!$B$10*(1+'Parámetros'!$B$13)^((7-1)/12))) | K10: =J10*'Parámetros'!$B$12 | L10: =MAX(0,C10-K10) | M10: =K10*('Parámetros'!$B$26*(1+'Parámetros'!$B$27)^((7-1)/12)) | N10: =N9+M10 | O10: =IF(7<='Parámetros'!$B$19,0,G10*'Parámetros'!$B$17/12) | P10: =D10+M10-O10 | Q10: =Q9+P10
A11: 8 | B11: =INT((8-1)/12)+1 | C11: =REDONDEAR(C10*(1-'Parámetros'!$B$7)^(1/12),0) | D11: =C11*'Parámetros'!$B$6 | E11: =E10+D11 | F11: =MAX(0, MIN('Parámetros'!$B$15-G10, D11*'Parámetros'!$B$16)) | G11: =G10+F11 | H11: =H10+IF(J11>J10,(J11-J10)*('Parámetros'!$B$12*'Parámetros'!$B$23*'Parámetros'!$B$21*'Parámetros'!$B$22*'Parámetros'!$B$24),0) | I11: =E11+G11+H11 | J11: =ENTERO(I11/('Parámetros'!$B$10*(1+'Parámetros'!$B$13)^((8-1)/12))) | K11: =J11*'Parámetros'!$B$12 | L11: =MAX(0,C11-K11) | M11: =K11*('Parámetros'!$B$26*(1+'Parámetros'!$B$27)^((8-1)/12)) | N11: =N10+M11 | O11: =IF(8<='Parámetros'!$B$19,0,G11*'Parámetros'!$B$17/12) | P11: =D11+M11-O11 | Q11: =Q10+P11
A12: 9 | B12: =INT((9-1)/12)+1 | C12: =REDONDEAR(C11*(1-'Parámetros'!$B$7)^(1/12),0) | D12: =C12*'Parámetros'!$B$6 | E12: =E11+D12 | F12: =MAX(0, MIN('Parámetros'!$B$15-G11, D12*'Parámetros'!$B$16)) | G12: =G11+F12 | H12: =H11+IF(J12>J11,(J12-J11)*('Parámetros'!$B$12*'Parámetros'!$B$23*'Parámetros'!$B$21*'Parámetros'!$B$22*'Parámetros'!$B$24),0) | I12: =E12+G12+H12 | J12: =ENTERO(I12/('Parámetros'!$B$10*(1+'Parámetros'!$B$13)^((9-1)/12))) | K12: =J12*'Parámetros'!$B$12 | L12: =MAX(0,C12-K12) | M12: =K12*('Parámetros'!$B$26*(1+'Parámetros'!$B$27)^((9-1)/12)) | N12: =N11+M12 | O12: =IF(9<='Parámetros'!$B$19,0,G12*'Parámetros'!$B$17/12) | P12: =D12+M12-O12 | Q12: =Q11+P12
A13: 10 | B13: =INT((10-1)/12)+1 | C13: =REDONDEAR(C12*(1-'Parámetros'!$B$7)^(1/12),0) | D13: =C13*'Parámetros'!$B$6 | E13: =E12+D13 | F13: =MAX(0, MIN('Parámetros'!$B$15-G12, D13*'Parámetros'!$B$16)) | G13: =G12+F13 | H13: =H12+IF(J13>J12,(J13-J12)*('Parámetros'!$B$12*'Parámetros'!$B$23*'Parámetros'!$B$21*'Parámetros'!$B$22*'Parámetros'!$B$24),0) | I13: =E13+G13+H13 | J13: =ENTERO(I13/('Parámetros'!$B$10*(1+'Parámetros'!$B$13)^((10-1)/12))) | K13: =J13*'Parámetros'!$B$12 | L13: =MAX(0,C13-K13) | M13: =K13*('Parámetros'!$B$26*(1+'Parámetros'!$B$27)^((10-1)/12)) | N13: =N12+M13 | O13: =IF(10<='Parámetros'!$B$19,0,G13*'Parámetros'!$B$17/12) | P13: =D13+M13-O13 | Q13: =Q12+P13
A14: 11 | B14: =INT((11-1)/12)+1 | C14: =REDONDEAR(C13*(1-'Parámetros'!$B$7)^(1/12),0) | D14: =C14*'Parámetros'!$B$6 | E14: =E13+D14 | F14: =MAX(0, MIN('Parámetros'!$B$15-G13, D14*'Parámetros'!$B$16)) | G14: =G13+F14 | H14: =H13+IF(J14>J13,(J14-J13)*('Parámetros'!$B$12*'Parámetros'!$B$23*'Parámetros'!$B$21*'Parámetros'!$B$22*'Parámetros'!$B$24),0) | I14: =E14+G14+H14 | J14: =ENTERO(I14/('Parámetros'!$B$10*(1+'Parámetros'!$B$13)^((11-1)/12))) | K14: =J14*'Parámetros'!$B$12 | L14: =MAX(0,C14-K14) | M14: =K14*('Parámetros'!$B$26*(1+'Parámetros'!$B$27)^((11-1)/12)) | N14: =N13+M14 | O14: =IF(11<='Parámetros'!$B$19,0,G14*'Parámetros'!$B$17/12) | P14: =D14+M14-O14 | Q14: =Q13+P14
A15: 12 | B15: =INT((12-1)/12)+1 | C15: =REDONDEAR(C14*(1-'Parámetros'!$B$7)^(1/12),0) | D15: =C15*'Parámetros'!$B$6 | E15: =E14+D15 | F15: =MAX(0, MIN('Parámetros'!$B$15-G14, D15*'Parámetros'!$B$16)) | G15: =G14+F15 | H15: =H14+IF(J15>J14,(J15-J14)*('Parámetros'!$B$12*'Parámetros'!$B$23*'Parámetros'!$B$21*'Parámetros'!$B$22*'Parámetros'!$B$24),0) | I15: =E15+G15+H15 | J15: =ENTERO(I15/('Parámetros'!$B$10*(1+'Parámetros'!$B$13)^((12-1)/12))) | K15: =J15*'Parámetros'!$B$12 | L15: =MAX(0,C15-K15) | M15: =K15*('Parámetros'!$B$26*(1+'Parámetros'!$B$27)^((12-1)/12)) | N15: =N14+M15 | O15: =IF(12<='Parámetros'!$B$19,0,G15*'Parámetros'!$B$17/12) | P15: =D15+M15-O15 | Q15: =Q14+P15
A16: 13 | B16: =INT((13-1)/12)+1 | C16: =REDONDEAR(C15*(1-'Parámetros'!$B$7)^(1/12),0) | D16: =C16*'Parámetros'!$B$6 | E16: =E15+D16 | F16: =MAX(0, MIN('Parámetros'!$B$15-G15, D16*'Parámetros'!$B$16)) | G16: =G15+F16 | H16: =H15+IF(J16>J15,(J16-J15)*('Parámetros'!$B$12*'Parámetros'!$B$23*'Parámetros'!$B$21*'Parámetros'!$B$22*'Parámetros'!$B$24),0) | I16: =E16+G16+H16 | J16: =ENTERO(I16/('Parámetros'!$B$10*(1+'Parámetros'!$B$13)^((13-1)/12))) | K16: =J16*'Parámetros'!$B$12 | L16: =MAX(0,C16-K16) | M16: =K16*('Parámetros'!$B$26*(1+'Parámetros'!$B$27)^((13-1)/12)) | N16: =N15+M16 | O16: =IF(13<='Parámetros'!$B$19,0,G16*'Parámetros'!$B$17/12) | P16: =D16+M16-O16 | Q16: =Q15+P16
A17: 14 | B17: =INT((14-1)/12)+1 | C17: =REDONDEAR(C16*(1-'Parámetros'!$B$7)^(1/12),0) | D17: =C17*'Parámetros'!$B$6 | E17: =E16+D17 | F17: =MAX(0, MIN('Parámetros'!$B$15-G16, D17*'Parámetros'!$B$16)) | G17: =G16+F17 | H17: =H16+IF(J17>J16,(J17-J16)*('Parámetros'!$B$12*'Parámetros'!$B$23*'Parámetros'!$B$21*'Parámetros'!$B$22*'Parámetros'!$B$24),0) | I17: =E17+G17+H17 | J17: =ENTERO(I17/('Parámetros'!$B$10*(1+'Parámetros'!$B$13)^((14-1)/12))) | K17: =J17*'Parámetros'!$B$12 | L17: =MAX(0,C17-K17) | M17: =K17*('Parámetros'!$B$26*(1+'Parámetros'!$B$27)^((14-1)/12)) | N17: =N16+M17 | O17: =IF(14<='Parámetros'!$B$19,0,G17*'Parámetros'!$B$17/12) | P17: =D17+M17-O17 | Q17: =Q16+P17
A18: 15 | B18: =INT((15-1)/12)+1 | C18: =REDONDEAR(C17*(1-'Parámetros'!$B$7)^(1/12),0) | D18: =C18*'Parámetros'!$B$6 | E18: =E17+D18 | F18: =MAX(0, MIN('Parámetros'!$B$15-G17, D18*'Parámetros'!$B$16)) | G18: =G17+F18 | H18: =H17+IF(J18>J17,(J18-J17)*('Parámetros'!$B$12*'Parámetros'!$B$23*'Parámetros'!$B$21*'Parámetros'!$B$22*'Parámetros'!$B$24),0) | I18: =E18+G18+H18 | J18: =ENTERO(I18/('Parámetros'!$B$10*(1+'Parámetros'!$B$13)^((15-1)/12))) | K18: =J18*'Parámetros'!$B$12 | L18: =MAX(0,C18-K18) | M18: =K18*('Parámetros'!$B$26*(1+'Parámetros'!$B$27)^((15-1)/12)) | N18: =N17+M18 | O18: =IF(15<='Parámetros'!$B$19,0,G18*'Parámetros'!$B$17/12) | P18: =D18+M18-O18 | Q18: =Q17+P18
A19: 16 | B19: =INT((16-1)/12)+1 | C19: =REDONDEAR(C18*(1-'Parámetros'!$B$7)^(1/12),0) | D19: =C19*'Parámetros'!$B$6 | E19: =E18+D19 | F19: =MAX(0, MIN('Parámetros'!$B$15-G18, D19*'Parámetros'!$B$16)) | G19: =G18+F19 | H19: =H18+IF(J19>J18,(J19-J18)*('Parámetros'!$B$12*'Parámetros'!$B$23*'Parámetros'!$B$21*'Parámetros'!$B$22*'Parámetros'!$B$24),0) | I19: =E19+G19+H19 | J19: =ENTERO(I19/('Parámetros'!$B$10*(1+'Parámetros'!$B$13)^((16-1)/12))) | K19: =J19*'Parámetros'!$B$12 | L19: =MAX(0,C19-K19) | M19: =K19*('Parámetros'!$B$26*(1+'Parámetros'!$B$27)^((16-1)/12)) | N19: =N18+M19 | O19: =IF(16<='Parámetros'!$B$19,0,G19*'Parámetros'!$B$17/12) | P19: =D19+M19-O19 | Q19: =Q18+P19
A20: 17 | B20: =INT((17-1)/12)+1 | C20: =REDONDEAR(C19*(1-'Parámetros'!$B$7)^(1/12),0) | D20: =C20*'Parámetros'!$B$6 | E20: =E19+D20 | F20: =MAX(0, MIN('Parámetros'!$B$15-G19, D20*'Parámetros'!$B$16)) | G20: =G19+F20 | H20: =H19+IF(J20>J19,(J20-J19)*('Parámetros'!$B$12*'Parámetros'!$B$23*'Parámetros'!$B$21*'Parámetros'!$B$22*'Parámetros'!$B$24),0) | I20: =E20+G20+H20 | J20: =ENTERO(I20/('Parámetros'!$B$10*(1+'Parámetros'!$B$13)^((17-1)/12))) | K20: =J20*'Parámetros'!$B$12 | L20: =MAX(0,C20-K20) | M20: =K20*('Parámetros'!$B$26*(1+'Parámetros'!$B$27)^((17-1)/12)) | N20: =N19+M20 | O20: =IF(17<='Parámetros'!$B$19,0,G20*'Parámetros'!$B$17/12) | P20: =D20+M20-O20 | Q20: =Q19+P20
A21: 18 | B21: =INT((18-1)/12)+1 | C21: =REDONDEAR(C20*(1-'Parámetros'!$B$7)^(1/12),0) | D21: =C21*'Parámetros'!$B$6 | E21: =E20+D21 | F21: =MAX(0, MIN('Parámetros'!$B$15-G20, D21*'Parámetros'!$B$16)) | G21: =G20+F21 | H21: =H20+IF(J21>J20,(J21-J20)*('Parámetros'!$B$12*'Parámetros'!$B$23*'Parámetros'!$B$21*'Parámetros'!$B$22*'Parámetros'!$B$24),0) | I21: =E21+G21+H21 | J21: =ENTERO(I21/('Parámetros'!$B$10*(1+'Parámetros'!$B$13)^((18-1)/12))) | K21: =J21*'Parámetros'!$B$12 | L21: =MAX(0,C21-K21) | M21: =K21*('Parámetros'!$B$26*(1+'Parámetros'!$B$27)^((18-1)/12)) | N21: =N20+M21 | O21: =IF(18<='Parámetros'!$B$19,0,G21*'Parámetros'!$B$17/12) | P21: =D21+M21-O21 | Q21: =Q20+P21
A22: 19 | B22: =INT((19-1)/12)+1 | C22: =REDONDEAR(C21*(1-'Parámetros'!$B$7)^(1/12),0) | D22: =C22*'Parámetros'!$B$6 | E22: =E21+D22 | F22: =MAX(0, MIN('Parámetros'!$B$15-G21, D22*'Parámetros'!$B$16)) | G22: =G21+F22 | H22: =H21+IF(J22>J21,(J22-J21)*('Parámetros'!$B$12*'Parámetros'!$B$23*'Parámetros'!$B$21*'Parámetros'!$B$22*'Parámetros'!$B$24),0) | I22: =E22+G22+H22 | J22: =ENTERO(I22/('Parámetros'!$B$10*(1+'Parámetros'!$B$13)^((19-1)/12))) | K22: =J22*'Parámetros'!$B$12 | L22: =MAX(0,C22-K22) | M22: =K22*('Parámetros'!$B$26*(1+'Parámetros'!$B$27)^((19-1)/12)) | N22: =N21+M22 | O22: =IF(19<='Parámetros'!$B$19,0,G22*'Parámetros'!$B$17/12) | P22: =D22+M22-O22 | Q22: =Q21+P22
A23: 20 | B23: =INT((20-1)/12)+1 | C23: =REDONDEAR(C22*(1-'Parámetros'!$B$7)^(1/12),0) | D23: =C23*'Parámetros'!$B$6 | E23: =E22+D23 | F23: =MAX(0, MIN('Parámetros'!$B$15-G22, D23*'Parámetros'!$B$16)) | G23: =G22+F23 | H23: =H22+IF(J23>J22,(J23-J22)*('Parámetros'!$B$12*'Parámetros'!$B$23*'Parámetros'!$B$21*'Parámetros'!$B$22*'Parámetros'!$B$24),0) | I23: =E23+G23+H23 | J23: =ENTERO(I23/('Parámetros'!$B$10*(1+'Parámetros'!$B$13)^((20-1)/12))) | K23: =J23*'Parámetros'!$B$12 | L23: =MAX(0,C23-K23) | M23: =K23*('Parámetros'!$B$26*(1+'Parámetros'!$B$27)^((20-1)/12)) | N23: =N22+M23 | O23: =IF(20<='Parámetros'!$B$19,0,G23*'Parámetros'!$B$17/12) | P23: =D23+M23-O23 | Q23: =Q22+P23
A24: 21 | B24: =INT((21-1)/12)+1 | C24: =REDONDEAR(C23*(1-'Parámetros'!$B$7)^(1/12),0) | D24: =C24*'Parámetros'!$B$6 | E24: =E23+D24 | F24: =MAX(0, MIN('Parámetros'!$B$15-G23, D24*'Parámetros'!$B$16)) | G24: =G23+F24 | H24: =H23+IF(J24>J23,(J24-J23)*('Parámetros'!$B$12*'Parámetros'!$B$23*'Parámetros'!$B$21*'Parámetros'!$B$22*'Parámetros'!$B$24),0) | I24: =E24+G24+H24 | J24: =ENTERO(I24/('Parámetros'!$B$10*(1+'Parámetros'!$B$13)^((21-1)/12))) | K24: =J24*'Parámetros'!$B$12 | L24: =MAX(0,C24-K24) | M24: =K24*('Parámetros'!$B$26*(1+'Parámetros'!$B$27)^((21-1)/12)) | N24: =N23+M24 | O24: =IF(21<='Parámetros'!$B$19,0,G24*'Parámetros'!$B$17/12) | P24: =D24+M24-O24 | Q24: =Q23+P24
A25: 22 | B25: =INT((22-1)/12)+1 | C25: =REDONDEAR(C24*(1-'Parámetros'!$B$7)^(1/12),0) | D25: =C25*'Parámetros'!$B$6 | E25: =E24+D25 | F25: =MAX(0, MIN('Parámetros'!$B$15-G24, D25*'Parámetros'!$B$16)) | G25: =G24+F25 | H25: =H24+IF(J25>J24,(J25-J24)*('Parámetros'!$B$12*'Parámetros'!$B$23*'Parámetros'!$B$21*'Parámetros'!$B$22*'Parámetros'!$B$24),0) | I25: =E25+G25+H25 | J25: =ENTERO(I25/('Parámetros'!$B$10*(1+'Parámetros'!$B$13)^((22-1)/12))) | K25: =J25*'Parámetros'!$B$12 | L25: =MAX(0,C25-K25) | M25: =K25*('Parámetros'!$B$26*(1+'Parámetros'!$B$27)^((22-1)/12)) | N25: =N24+M25 | O25: =IF(22<='Parámetros'!$B$19,0,G25*'Parámetros'!$B$17/12) | P25: =D25+M25-O25 | Q25: =Q24+P25
A26: 23 | B26: =INT((23-1)/12)+1 | C26: =REDONDEAR(C25*(1-'Parámetros'!$B$7)^(1/12),0) | D26: =C26*'Parámetros'!$B$6 | E26: =E25+D26 | F26: =MAX(0, MIN('Parámetros'!$B$15-G25, D26*'Parámetros'!$B$16)) | G26: =G25+F26 | H26: =H25+IF(J26>J25,(J26-J25)*('Parámetros'!$B$12*'Parámetros'!$B$23*'Parámetros'!$B$21*'Parámetros'!$B$22*'Parámetros'!$B$24),0) | I26: =E26+G26+H26 | J26: =ENTERO(I26/('Parámetros'!$B$10*(1+'Parámetros'!$B$13)^((23-1)/12))) | K26: =J26*'Parámetros'!$B$12 | L26: =MAX(0,C26-K26) | M26: =K26*('Parámetros'!$B$26*(1+'Parámetros'!$B$27)^((23-1)/12)) | N26: =N25+M26 | O26: =IF(23<='Parámetros'!$B$19,0,G26*'Parámetros'!$B$17/12) | P26: =D26+M26-O26 | Q26: =Q25+P26
A27: 24 | B27: =INT((24-1)/12)+1 | C27: =REDONDEAR(C26*(1-'Parámetros'!$B$7)^(1/12),0) | D27: =C27*'Parámetros'!$B$6 | E27: =E26+D27 | F27: =MAX(0, MIN('Parámetros'!$B$15-G26, D27*'Parámetros'!$B$16)) | G27: =G26+F27 | H27: =H26+IF(J27>J26,(J27-J26)*('Parámetros'!$B$12*'Parámetros'!$B$23*'Parámetros'!$B$21*'Parámetros'!$B$22*'Parámetros'!$B$24),0) | I27: =E27+G27+H27 | J27: =ENTERO(I27/('Parámetros'!$B$10*(1+'Parámetros'!$B$13)^((24-1)/12))) | K27: =J27*'Parámetros'!$B$12 | L27: =MAX(0,C27-K27) | M27: =K27*('Parámetros'!$B$26*(1+'Parámetros'!$B$27)^((24-1)/12)) | N27: =N26+M27 | O27: =IF(24<='Parámetros'!$B$19,0,G27*'Parámetros'!$B$17/12) | P27: =D27+M27-O27 | Q27: =Q26+P27
A28: 25 | B28: =INT((25-1)/12)+1 | C28: =REDONDEAR(C27*(1-'Parámetros'!$B$7)^(1/12),0) | D28: =C28*'Parámetros'!$B$6 | E28: =E27+D28 | F28: =MAX(0, MIN('Parámetros'!$B$15-G27, D28*'Parámetros'!$B$16)) | G28: =G27+F28 | H28: =H27+IF(J28>J27,(J28-J27)*('Parámetros'!$B$12*'Parámetros'!$B$23*'Parámetros'!$B$21*'Parámetros'!$B$22*'Parámetros'!$B$24),0) | I28: =E28+G28+H28 | J28: =ENTERO(I28/('Parámetros'!$B$10*(1+'Parámetros'!$B$13)^((25-1)/12))) | K28: =J28*'Parámetros'!$B$12 | L28: =MAX(0,C28-K28) | M28: =K28*('Parámetros'!$B$26*(1+'Parámetros'!$B$27)^((25-1)/12)) | N28: =N27+M28 | O28: =IF(25<='Parámetros'!$B$19,0,G28*'Parámetros'!$B$17/12) | P28: =D28+M28-O28 | Q28: =Q27+P28
A29: 26 | B29: =INT((26-1)/12)+1 | C29: =REDONDEAR(C28*(1-'Parámetros'!$B$7)^(1/12),0) | D29: =C29*'Parámetros'!$B$6 | E29: =E28+D29 | F29: =MAX(0, MIN('Parámetros'!$B$15-G28, D29*'Parámetros'!$B$16)) | G29: =G28+F29 | H29: =H28+IF(J29>J28,(J29-J28)*('Parámetros'!$B$12*'Parámetros'!$B$23*'Parámetros'!$B$21*'Parámetros'!$B$22*'Parámetros'!$B$24),0) | I29: =E29+G29+H29 | J29: =ENTERO(I29/('Parámetros'!$B$10*(1+'Parámetros'!$B$13)^((26-1)/12))) | K29: =J29*'Parámetros'!$B$12 | L29: =MAX(0,C29-K29) | M29: =K29*('Parámetros'!$B$26*(1+'Parámetros'!$B$27)^((26-1)/12)) | N29: =N28+M29 | O29: =IF(26<='Parámetros'!$B$19,0,G29*'Parámetros'!$B$17/12) | P29: =D29+M29-O29 | Q29: =Q28+P29
A30: 27 | B30: =INT((27-1)/12)+1 | C30: =REDONDEAR(C29*(1-'Parámetros'!$B$7)^(1/12),0) | D30: =C30*'Parámetros'!$B$6 | E30: =E29+D30 | F30: =MAX(0, MIN('Parámetros'!$B$15-G29, D30*'Parámetros'!$B$16)) | G30: =G29+F30 | H30: =H29+IF(J30>J29,(J30-J29)*('Parámetros'!$B$12*'Parámetros'!$B$23*'Parámetros'!$B$21*'Parámetros'!$B$22*'Parámetros'!$B$24),0) | I30: =E30+G30+H30 | J30: =ENTERO(I30/('Parámetros'!$B$10*(1+'Parámetros'!$B$13)^((27-1)/12))) | K30: =J30*'Parámetros'!$B$12 | L30: =MAX(0,C30-K30) | M30: =K30*('Parámetros'!$B$26*(1+'Parámetros'!$B$27)^((27-1)/12)) | N30: =N29+M30 | O30: =IF(27<='Parámetros'!$B$19,0,G30*'Parámetros'!$B$17/12) | P30: =D30+M30-O30 | Q30: =Q29+P30
A31: 28 | B31: =INT((28-1)/12)+1 | C31: =REDONDEAR(C30*(1-'Parámetros'!$B$7)^(1/12),0) | D31: =C31*'Parámetros'!$B$6 | E31: =E30+D31 | F31: =MAX(0, MIN('Parámetros'!$B$15-G30, D31*'Parámetros'!$B$16)) | G31: =G30+F31 | H31: =H30+IF(J31>J30,(J31-J30)*('Parámetros'!$B$12*'Parámetros'!$B$23*'Parámetros'!$B$21*'Parámetros'!$B$22*'Parámetros'!$B$24),0) | I31: =E31+G31+H31 | J31: =ENTERO(I31/('Parámetros'!$B$10*(1+'Parámetros'!$B$13)^((28-1)/12))) | K31: =J31*'Parámetros'!$B$12 | L31: =MAX(0,C31-K31) | M31: =K31*('Parámetros'!$B$26*(1+'Parámetros'!$B$27)^((28-1)/12)) | N31: =N30+M31 | O31: =IF(28<='Parámetros'!$B$19,0,G31*'Parámetros'!$B$17/12) | P31: =D31+M31-O31 | Q31: =Q30+P31
A32: 29 | B32: =INT((29-1)/12)+1 | C32: =REDONDEAR(C31*(1-'Parámetros'!$B$7)^(1/12),0) | D32: =C32*'Parámetros'!$B$6 | E32: =E31+D32 | F32: =MAX(0, MIN('Parámetros'!$B$15-G31, D32*'Parámetros'!$B$16)) | G32: =G31+F32 | H32: =H31+IF(J32>J31,(J32-J31)*('Parámetros'!$B$12*'Parámetros'!$B$23*'Parámetros'!$B$21*'Parámetros'!$B$22*'Parámetros'!$B$24),0) | I32: =E32+G32+H32 | J32: =ENTERO(I32/('Parámetros'!$B$10*(1+'Parámetros'!$B$13)^((29-1)/12))) | K32: =J32*'Parámetros'!$B$12 | L32: =MAX(0,C32-K32) | M32: =K32*('Parámetros'!$B$26*(1+'Parámetros'!$B$27)^((29-1)/12)) | N32: =N31+M32 | O32: =IF(29<='Parámetros'!$B$19,0,G32*'Parámetros'!$B$17/12) | P32: =D32+M32-O32 | Q32: =Q31+P32
A33: 30 | B33: =INT((30-1)/12)+1 | C33: =REDONDEAR(C32*(1-'Parámetros'!$B$7)^(1/12),0) | D33: =C33*'Parámetros'!$B$6 | E33: =E32+D33 | F33: =MAX(0, MIN('Parámetros'!$B$15-G32, D33*'Parámetros'!$B$16)) | G33: =G32+F33 | H33: =H32+IF(J33>J32,(J33-J32)*('Parámetros'!$B$12*'Parámetros'!$B$23*'Parámetros'!$B$21*'Parámetros'!$B$22*'Parámetros'!$B$24),0) | I33: =E33+G33+H33 | J33: =ENTERO(I33/('Parámetros'!$B$10*(1+'Parámetros'!$B$13)^((30-1)/12))) | K33: =J33*'Parámetros'!$B$12 | L33: =MAX(0,C33-K33) | M33: =K33*('Parámetros'!$B$26*(1+'Parámetros'!$B$27)^((30-1)/12)) | N33: =N32+M33 | O33: =IF(30<='Parámetros'!$B$19,0,G33*'Parámetros'!$B$17/12) | P33: =D33+M33-O33 | Q33: =Q32+P33
A34: 31 | B34: =INT((31-1)/12)+1 | C34: =REDONDEAR(C33*(1-'Parámetros'!$B$7)^(1/12),0) | D34: =C34*'Parámetros'!$B$6 | E34: =E33+D34 | F34: =MAX(0, MIN('Parámetros'!$B$15-G33, D34*'Parámetros'!$B$16)) | G34: =G33+F34 | H34: =H33+IF(J34>J33,(J34-J33)*('Parámetros'!$B$12*'Parámetros'!$B$23*'Parámetros'!$B$21*'Parámetros'!$B$22*'Parámetros'!$B$24),0) | I34: =E34+G34+H34 | J34: =ENTERO(I34/('Parámetros'!$B$10*(1+'Parámetros'!$B$13)^((31-1)/12))) | K34: =J34*'Parámetros'!$B$12 | L34: =MAX(0,C34-K34) | M34: =K34*('Parámetros'!$B$26*(1+'Parámetros'!$B$27)^((31-1)/12)) | N34: =N33+M34 | O34: =IF(31<='Parámetros'!$B$19,0,G34*'Parámetros'!$B$17/12) | P34: =D34+M34-O34 | Q34: =Q33+P34
A35: 32 | B35: =INT((32-1)/12)+1 | C35: =REDONDEAR(C34*(1-'Parámetros'!$B$7)^(1/12),0) | D35: =C35*'Parámetros'!$B$6 | E35: =E34+D35 | F35: =MAX(0, MIN('Parámetros'!$B$15-G34, D35*'Parámetros'!$B$16)) | G35: =G34+F35 | H35: =H34+IF(J35>J34,(J35-J34)*('Parámetros'!$B$12*'Parámetros'!$B$23*'Parámetros'!$B$21*'Parámetros'!$B$22*'Parámetros'!$B$24),0) | I35: =E35+G35+H35 | J35: =ENTERO(I35/('Parámetros'!$B$10*(1+'Parámetros'!$B$13)^((32-1)/12))) | K35: =J35*'Parámetros'!$B$12 | L35: =MAX(0,C35-K35) | M35: =K35*('Parámetros'!$B$26*(1+'Parámetros'!$B$27)^((32-1)/12)) | N35: =N34+M35 | O35: =IF(32<='Parámetros'!$B$19,0,G35*'Parámetros'!$B$17/12) | P35: =D35+M35-O35 | Q35: =Q34+P35
A36: 33 | B36: =INT((33-1)/12)+1 | C36: =REDONDEAR(C35*(1-'Parámetros'!$B$7)^(1/12),0) | D36: =C36*'Parámetros'!$B$6 | E36: =E35+D36 | F36: =MAX(0, MIN('Parámetros'!$B$15-G35, D36*'Parámetros'!$B$16)) | G36: =G35+F36 | H36: =H35+IF(J36>J35,(J36-J35)*('Parámetros'!$B$12*'Parámetros'!$B$23*'Parámetros'!$B$21*'Parámetros'!$B$22*'Parámetros'!$B$24),0) | I36: =E36+G36+H36 | J36: =ENTERO(I36/('Parámetros'!$B$10*(1+'Parámetros'!$B$13)^((33-1)/12))) | K36: =J36*'Parámetros'!$B$12 | L36: =MAX(0,C36-K36) | M36: =K36*('Parámetros'!$B$26*(1+'Parámetros'!$B$27)^((33-1)/12)) | N36: =N35+M36 | O36: =IF(33<='Parámetros'!$B$19,0,G36*'Parámetros'!$B$17/12) | P36: =D36+M36-O36 | Q36: =Q35+P36
A37: 34 | B37: =INT((34-1)/12)+1 | C37: =REDONDEAR(C36*(1-'Parámetros'!$B$7)^(1/12),0) | D37: =C37*'Parámetros'!$B$6 | E37: =E36+D37 | F37: =MAX(0, MIN('Parámetros'!$B$15-G36, D37*'Parámetros'!$B$16)) | G37: =G36+F37 | H37: =H36+IF(J37>J36,(J37-J36)*('Parámetros'!$B$12*'Parámetros'!$B$23*'Parámetros'!$B$21*'Parámetros'!$B$22*'Parámetros'!$B$24),0) | I37: =E37+G37+H37 | J37: =ENTERO(I37/('Parámetros'!$B$10*(1+'Parámetros'!$B$13)^((34-1)/12))) | K37: =J37*'Parámetros'!$B$12 | L37: =MAX(0,C37-K37) | M37: =K37*('Parámetros'!$B$26*(1+'Parámetros'!$B$27)^((34-1)/12)) | N37: =N36+M37 | O37: =IF(34<='Parámetros'!$B$19,0,G37*'Parámetros'!$B$17/12) | P37: =D37+M37-O37 | Q37: =Q36+P37
A38: 35 | B38: =INT((35-1)/12)+1 | C38: =REDONDEAR(C37*(1-'Parámetros'!$B$7)^(1/12),0) | D38: =C38*'Parámetros'!$B$6 | E38: =E37+D38 | F38: =MAX(0, MIN('Parámetros'!$B$15-G37, D38*'Parámetros'!$B$16)) | G38: =G37+F38 | H38: =H37+IF(J38>J37,(J38-J37)*('Parámetros'!$B$12*'Parámetros'!$B$23*'Parámetros'!$B$21*'Parámetros'!$B$22*'Parámetros'!$B$24),0) | I38: =E38+G38+H38 | J38: =ENTERO(I38/('Parámetros'!$B$10*(1+'Parámetros'!$B$13)^((35-1)/12))) | K38: =J38*'Parámetros'!$B$12 | L38: =MAX(0,C38-K38) | M38: =K38*('Parámetros'!$B$26*(1+'Parámetros'!$B$27)^((35-1)/12)) | N38: =N37+M38 | O38: =IF(35<='Parámetros'!$B$19,0,G38*'Parámetros'!$B$17/12) | P38: =D38+M38-O38 | Q38: =Q37+P38
A39: 36 | B39: =INT((36-1)/12)+1 | C39: =REDONDEAR(C38*(1-'Parámetros'!$B$7)^(1/12),0) | D39: =C39*'Parámetros'!$B$6 | E39: =E38+D39 | F39: =MAX(0, MIN('Parámetros'!$B$15-G38, D39*'Parámetros'!$B$16)) | G39: =G38+F39 | H39: =H38+IF(J39>J38,(J39-J38)*('Parámetros'!$B$12*'Parámetros'!$B$23*'Parámetros'!$B$21*'Parámetros'!$B$22*'Parámetros'!$B$24),0) | I39: =E39+G39+H39 | J39: =ENTERO(I39/('Parámetros'!$B$10*(1+'Parámetros'!$B$13)^((36-1)/12))) | K39: =J39*'Parámetros'!$B$12 | L39: =MAX(0,C39-K39) | M39: =K39*('Parámetros'!$B$26*(1+'Parámetros'!$B$27)^((36-1)/12)) | N39: =N38+M39 | O39: =IF(36<='Parámetros'!$B$19,0,G39*'Parámetros'!$B$17/12) | P39: =D39+M39-O39 | Q39: =Q38+P39
A40: 37 | B40: =INT((37-1)/12)+1 | C40: =REDONDEAR(C39*(1-'Parámetros'!$B$7)^(1/12),0) | D40: =C40*'Parámetros'!$B$6 | E40: =E39+D40 | F40: =MAX(0, MIN('Parámetros'!$B$15-G39, D40*'Parámetros'!$B$16)) | G40: =G39+F40 | H40: =H39+IF(J40>J39,(J40-J39)*('Parámetros'!$B$12*'Parámetros'!$B$23*'Parámetros'!$B$21*'Parámetros'!$B$22*'Parámetros'!$B$24),0) | I40: =E40+G40+H40 | J40: =ENTERO(I40/('Parámetros'!$B$10*(1+'Parámetros'!$B$13)^((37-1)/12))) | K40: =J40*'Parámetros'!$B$12 | L40: =MAX(0,C40-K40) | M40: =K40*('Parámetros'!$B$26*(1+'Parámetros'!$B$27)^((37-1)/12)) | N40: =N39+M40 | O40: =IF(37<='Parámetros'!$B$19,0,G40*'Parámetros'!$B$17/12) | P40: =D40+M40-O40 | Q40: =Q39+P40
...

Sheet Análisis de Sensibilidad
A1: ANÁLISIS DE SENSIBILIDAD — Tablas Bidimensionales
A2: Nota: Las tablas de sensibilidad muestran cálculos directos basados en las fórmulas del modelo. Cambiar los parámetros en la hoja 'Parámetros' actualiza todos los resultados.
A4: TABLA 1 — Terrenos Adquiridos a 5 Años (mes 60)
A5: Familias \ Cuota | B5: 20000 | C5: 25000 | D5: 30000 | E5: 35000 | F5: 40000
A6: 100 | B6: =LET(des_mes,(1-'Parámetros'!$B$7)^(1/12),acum_c1,20000*100*(1-des_mes^60)/(1-des_mes),acum_c2,MIN('Parámetros'!$B$15,acum_c1*'Parámetros'!$B$16),sub_por_t,'Parámetros'!$B$12*'Parámetros'!$B$23*'Parámetros'!$B$21*'Parámetros'!$B$22*'Parámetros'!$B$24,cap_total,acum_c1+acum_c2,precio_adj,'Parámetros'!$B$10*(1+'Parámetros'!$B$13)^(60/12),terrenos_aprox,MAX(0,ENTERO(cap_total/precio_adj)),ENTERO((cap_total+terrenos_aprox*sub_por_t)/precio_adj)) | C6: =LET(des_mes,(1-'Parámetros'!$B$7)^(1/12),acum_c1,25000*100*(1-des_mes^60)/(1-des_mes),acum_c2,MIN('Parámetros'!$B$15,acum_c1*'Parámetros'!$B$16),sub_por_t,'Parámetros'!$B$12*'Parámetros'!$B$23*'Parámetros'!$B$21*'Parámetros'!$B$22*'Parámetros'!$B$24,cap_total,acum_c1+acum_c2,precio_adj,'Parámetros'!$B$10*(1+'Parámetros'!$B$13)^(60/12),terrenos_aprox,MAX(0,ENTERO(cap_total/precio_adj)),ENTERO((cap_total+terrenos_aprox*sub_por_t)/precio_adj)) | D6: =LET(des_mes,(1-'Parámetros'!$B$7)^(1/12),acum_c1,30000*100*(1-des_mes^60)/(1-des_mes),acum_c2,MIN('Parámetros'!$B$15,acum_c1*'Parámetros'!$B$16),sub_por_t,'Parámetros'!$B$12*'Parámetros'!$B$23*'Parámetros'!$B$21*'Parámetros'!$B$22*'Parámetros'!$B$24,cap_total,acum_c1+acum_c2,precio_adj,'Parámetros'!$B$10*(1+'Parámetros'!$B$13)^(60/12),terrenos_aprox,MAX(0,ENTERO(cap_total/precio_adj)),ENTERO((cap_total+terrenos_aprox*sub_por_t)/precio_adj)) | E6: =LET(des_mes,(1-'Parámetros'!$B$7)^(1/12),acum_c1,35000*100*(1-des_mes^60)/(1-des_mes),acum_c2,MIN('Parámetros'!$B$15,acum_c1*'Parámetros'!$B$16),sub_por_t,'Parámetros'!$B$12*'Parámetros'!$B$23*'Parámetros'!$B$21*'Parámetros'!$B$22*'Parámetros'!$B$24,cap_total,acum_c1+acum_c2,precio_adj,'Parámetros'!$B$10*(1+'Parámetros'!$B$13)^(60/12),terrenos_aprox,MAX(0,ENTERO(cap_total/precio_adj)),ENTERO((cap_total+terrenos_aprox*sub_por_t)/precio_adj)) | F6: =LET(des_mes,(1-'Parámetros'!$B$7)^(1/12),acum_c1,40000*100*(1-des_mes^60)/(1-des_mes),acum_c2,MIN('Parámetros'!$B$15,acum_c1*'Parámetros'!$B$16),sub_por_t,'Parámetros'!$B$12*'Parámetros'!$B$23*'Parámetros'!$B$21*'Parámetros'!$B$22*'Parámetros'!$B$24,cap_total,acum_c1+acum_c2,precio_adj,'Parámetros'!$B$10*(1+'Parámetros'!$B$13)^(60/12),terrenos_aprox,MAX(0,ENTERO(cap_total/precio_adj)),ENTERO((cap_total+terrenos_aprox*sub_por_t)/precio_adj))
A7: 200 | B7: =LET(des_mes,(1-'Parámetros'!$B$7)^(1/12),acum_c1,20000*200*(1-des_mes^60)/(1-des_mes),acum_c2,MIN('Parámetros'!$B$15,acum_c1*'Parámetros'!$B$16),sub_por_t,'Parámetros'!$B$12*'Parámetros'!$B$23*'Parámetros'!$B$21*'Parámetros'!$B$22*'Parámetros'!$B$24,cap_total,acum_c1+acum_c2,precio_adj,'Parámetros'!$B$10*(1+'Parámetros'!$B$13)^(60/12),terrenos_aprox,MAX(0,ENTERO(cap_total/precio_adj)),ENTERO((cap_total+terrenos_aprox*sub_por_t)/precio_adj)) | C7: =LET(des_mes,(1-'Parámetros'!$B$7)^(1/12),acum_c1,25000*200*(1-des_mes^60)/(1-des_mes),acum_c2,MIN('Parámetros'!$B$15,acum_c1*'Parámetros'!$B$16),sub_por_t,'Parámetros'!$B$12*'Parámetros'!$B$23*'Parámetros'!$B$21*'Parámetros'!$B$22*'Parámetros'!$B$24,cap_total,acum_c1+acum_c2,precio_adj,'Parámetros'!$B$10*(1+'Parámetros'!$B$13)^(60/12),terrenos_aprox,MAX(0,ENTERO(cap_total/precio_adj)),ENTERO((cap_total+terrenos_aprox*sub_por_t)/precio_adj)) | D7: =LET(des_mes,(1-'Parámetros'!$B$7)^(1/12),acum_c1,30000*200*(1-des_mes^60)/(1-des_mes),acum_c2,MIN('Parámetros'!$B$15,acum_c1*'Parámetros'!$B$16),sub_por_t,'Parámetros'!$B$12*'Parámetros'!$B$23*'Parámetros'!$B$21*'Parámetros'!$B$22*'Parámetros'!$B$24,cap_total,acum_c1+acum_c2,precio_adj,'Parámetros'!$B$10*(1+'Parámetros'!$B$13)^(60/12),terrenos_aprox,MAX(0,ENTERO(cap_total/precio_adj)),ENTERO((cap_total+terrenos_aprox*sub_por_t)/precio_adj)) | E7: =LET(des_mes,(1-'Parámetros'!$B$7)^(1/12),acum_c1,35000*200*(1-des_mes^60)/(1-des_mes),acum_c2,MIN('Parámetros'!$B$15,acum_c1*'Parámetros'!$B$16),sub_por_t,'Parámetros'!$B$12*'Parámetros'!$B$23*'Parámetros'!$B$21*'Parámetros'!$B$22*'Parámetros'!$B$24,cap_total,acum_c1+acum_c2,precio_adj,'Parámetros'!$B$10*(1+'Parámetros'!$B$13)^(60/12),terrenos_aprox,MAX(0,ENTERO(cap_total/precio_adj)),ENTERO((cap_total+terrenos_aprox*sub_por_t)/precio_adj)) | F7: =LET(des_mes,(1-'Parámetros'!$B$7)^(1/12),acum_c1,40000*200*(1-des_mes^60)/(1-des_mes),acum_c2,MIN('Parámetros'!$B$15,acum_c1*'Parámetros'!$B$16),sub_por_t,'Parámetros'!$B$12*'Parámetros'!$B$23*'Parámetros'!$B$21*'Parámetros'!$B$22*'Parámetros'!$B$24,cap_total,acum_c1+acum_c2,precio_adj,'Parámetros'!$B$10*(1+'Parámetros'!$B$13)^(60/12),terrenos_aprox,MAX(0,ENTERO(cap_total/precio_adj)),ENTERO((cap_total+terrenos_aprox*sub_por_t)/precio_adj))
A8: 300 | B8: =LET(des_mes,(1-'Parámetros'!$B$7)^(1/12),acum_c1,20000*300*(1-des_mes^60)/(1-des_mes),acum_c2,MIN('Parámetros'!$B$15,acum_c1*'Parámetros'!$B$16),sub_por_t,'Parámetros'!$B$12*'Parámetros'!$B$23*'Parámetros'!$B$21*'Parámetros'!$B$22*'Parámetros'!$B$24,cap_total,acum_c1+acum_c2,precio_adj,'Parámetros'!$B$10*(1+'Parámetros'!$B$13)^(60/12),terrenos_aprox,MAX(0,ENTERO(cap_total/precio_adj)),ENTERO((cap_total+terrenos_aprox*sub_por_t)/precio_adj)) | C8: =LET(des_mes,(1-'Parámetros'!$B$7)^(1/12),acum_c1,25000*300*(1-des_mes^60)/(1-des_mes),acum_c2,MIN('Parámetros'!$B$15,acum_c1*'Parámetros'!$B$16),sub_por_t,'Parámetros'!$B$12*'Parámetros'!$B$23*'Parámetros'!$B$21*'Parámetros'!$B$22*'Parámetros'!$B$24,cap_total,acum_c1+acum_c2,precio_adj,'Parámetros'!$B$10*(1+'Parámetros'!$B$13)^(60/12),terrenos_aprox,MAX(0,ENTERO(cap_total/precio_adj)),ENTERO((cap_total+terrenos_aprox*sub_por_t)/precio_adj)) | D8: =LET(des_mes,(1-'Parámetros'!$B$7)^(1/12),acum_c1,30000*300*(1-des_mes^60)/(1-des_mes),acum_c2,MIN('Parámetros'!$B$15,acum_c1*'Parámetros'!$B$16),sub_por_t,'Parámetros'!$B$12*'Parámetros'!$B$23*'Parámetros'!$B$21*'Parámetros'!$B$22*'Parámetros'!$B$24,cap_total,acum_c1+acum_c2,precio_adj,'Parámetros'!$B$10*(1+'Parámetros'!$B$13)^(60/12),terrenos_aprox,MAX(0,ENTERO(cap_total/precio_adj)),ENTERO((cap_total+terrenos_aprox*sub_por_t)/precio_adj)) | E8: =LET(des_mes,(1-'Parámetros'!$B$7)^(1/12),acum_c1,35000*300*(1-des_mes^60)/(1-des_mes),acum_c2,MIN('Parámetros'!$B$15,acum_c1*'Parámetros'!$B$16),sub_por_t,'Parámetros'!$B$12*'Parámetros'!$B$23*'Parámetros'!$B$21*'Parámetros'!$B$22*'Parámetros'!$B$24,cap_total,acum_c1+acum_c2,precio_adj,'Parámetros'!$B$10*(1+'Parámetros'!$B$13)^(60/12),terrenos_aprox,MAX(0,ENTERO(cap_total/precio_adj)),ENTERO((cap_total+terrenos_aprox*sub_por_t)/precio_adj)) | F8: =LET(des_mes,(1-'Parámetros'!$B$7)^(1/12),acum_c1,40000*300*(1-des_mes^60)/(1-des_mes),acum_c2,MIN('Parámetros'!$B$15,acum_c1*'Parámetros'!$B$16),sub_por_t,'Parámetros'!$B$12*'Parámetros'!$B$23*'Parámetros'!$B$21*'Parámetros'!$B$22*'Parámetros'!$B$24,cap_total,acum_c1+acum_c2,precio_adj,'Parámetros'!$B$10*(1+'Parámetros'!$B$13)^(60/12),terrenos_aprox,MAX(0,ENTERO(cap_total/precio_adj)),ENTERO((cap_total+terrenos_aprox*sub_por_t)/precio_adj))
A9: 500 | B9: =LET(des_mes,(1-'Parámetros'!$B$7)^(1/12),acum_c1,20000*500*(1-des_mes^60)/(1-des_mes),acum_c2,MIN('Parámetros'!$B$15,acum_c1*'Parámetros'!$B$16),sub_por_t,'Parámetros'!$B$12*'Parámetros'!$B$23*'Parámetros'!$B$21*'Parámetros'!$B$22*'Parámetros'!$B$24,cap_total,acum_c1+acum_c2,precio_adj,'Parámetros'!$B$10*(1+'Parámetros'!$B$13)^(60/12),terrenos_aprox,MAX(0,ENTERO(cap_total/precio_adj)),ENTERO((cap_total+terrenos_aprox*sub_por_t)/precio_adj)) | C9: =LET(des_mes,(1-'Parámetros'!$B$7)^(1/12),acum_c1,25000*500*(1-des_mes^60)/(1-des_mes),acum_c2,MIN('Parámetros'!$B$15,acum_c1*'Parámetros'!$B$16),sub_por_t,'Parámetros'!$B$12*'Parámetros'!$B$23*'Parámetros'!$B$21*'Parámetros'!$B$22*'Parámetros'!$B$24,cap_total,acum_c1+acum_c2,precio_adj,'Parámetros'!$B$10*(1+'Parámetros'!$B$13)^(60/12),terrenos_aprox,MAX(0,ENTERO(cap_total/precio_adj)),ENTERO((cap_total+terrenos_aprox*sub_por_t)/precio_adj)) | D9: =LET(des_mes,(1-'Parámetros'!$B$7)^(1/12),acum_c1,30000*500*(1-des_mes^60)/(1-des_mes),acum_c2,MIN('Parámetros'!$B$15,acum_c1*'Parámetros'!$B$16),sub_por_t,'Parámetros'!$B$12*'Parámetros'!$B$23*'Parámetros'!$B$21*'Parámetros'!$B$22*'Parámetros'!$B$24,cap_total,acum_c1+acum_c2,precio_adj,'Parámetros'!$B$10*(1+'Parámetros'!$B$13)^(60/12),terrenos_aprox,MAX(0,ENTERO(cap_total/precio_adj)),ENTERO((cap_total+terrenos_aprox*sub_por_t)/precio_adj)) | E9: =LET(des_mes,(1-'Parámetros'!$B$7)^(1/12),acum_c1,35000*500*(1-des_mes^60)/(1-des_mes),acum_c2,MIN('Parámetros'!$B$15,acum_c1*'Parámetros'!$B$16),sub_por_t,'Parámetros'!$B$12*'Parámetros'!$B$23*'Parámetros'!$B$21*'Parámetros'!$B$22*'Parámetros'!$B$24,cap_total,acum_c1+acum_c2,precio_adj,'Parámetros'!$B$10*(1+'Parámetros'!$B$13)^(60/12),terrenos_aprox,MAX(0,ENTERO(cap_total/precio_adj)),ENTERO((cap_total+terrenos_aprox*sub_por_t)/precio_adj)) | F9: =LET(des_mes,(1-'Parámetros'!$B$7)^(1/12),acum_c1,40000*500*(1-des_mes^60)/(1-des_mes),acum_c2,MIN('Parámetros'!$B$15,acum_c1*'Parámetros'!$B$16),sub_por_t,'Parámetros'!$B$12*'Parámetros'!$B$23*'Parámetros'!$B$21*'Parámetros'!$B$22*'Parámetros'!$B$24,cap_total,acum_c1+acum_c2,precio_adj,'Parámetros'!$B$10*(1+'Parámetros'!$B$13)^(60/12),terrenos_aprox,MAX(0,ENTERO(cap_total/precio_adj)),ENTERO((cap_total+terrenos_aprox*sub_por_t)/precio_adj))
A10: 1000 | B10: =LET(des_mes,(1-'Parámetros'!$B$7)^(1/12),acum_c1,20000*1000*(1-des_mes^60)/(1-des_mes),acum_c2,MIN('Parámetros'!$B$15,acum_c1*'Parámetros'!$B$16),sub_por_t,'Parámetros'!$B$12*'Parámetros'!$B$23*'Parámetros'!$B$21*'Parámetros'!$B$22*'Parámetros'!$B$24,cap_total,acum_c1+acum_c2,precio_adj,'Parámetros'!$B$10*(1+'Parámetros'!$B$13)^(60/12),terrenos_aprox,MAX(0,ENTERO(cap_total/precio_adj)),ENTERO((cap_total+terrenos_aprox*sub_por_t)/precio_adj)) | C10: =LET(des_mes,(1-'Parámetros'!$B$7)^(1/12),acum_c1,25000*1000*(1-des_mes^60)/(1-des_mes),acum_c2,MIN('Parámetros'!$B$15,acum_c1*'Parámetros'!$B$16),sub_por_t,'Parámetros'!$B$12*'Parámetros'!$B$23*'Parámetros'!$B$21*'Parámetros'!$B$22*'Parámetros'!$B$24,cap_total,acum_c1+acum_c2,precio_adj,'Parámetros'!$B$10*(1+'Parámetros'!$B$13)^(60/12),terrenos_aprox,MAX(0,ENTERO(cap_total/precio_adj)),ENTERO((cap_total+terrenos_aprox*sub_por_t)/precio_adj)) | D10: =LET(des_mes,(1-'Parámetros'!$B$7)^(1/12),acum_c1,30000*1000*(1-des_mes^60)/(1-des_mes),acum_c2,MIN('Parámetros'!$B$15,acum_c1*'Parámetros'!$B$16),sub_por_t,'Parámetros'!$B$12*'Parámetros'!$B$23*'Parámetros'!$B$21*'Parámetros'!$B$22*'Parámetros'!$B$24,cap_total,acum_c1+acum_c2,precio_adj,'Parámetros'!$B$10*(1+'Parámetros'!$B$13)^(60/12),terrenos_aprox,MAX(0,ENTERO(cap_total/precio_adj)),ENTERO((cap_total+terrenos_aprox*sub_por_t)/precio_adj)) | E10: =LET(des_mes,(1-'Parámetros'!$B$7)^(1/12),acum_c1,35000*1000*(1-des_mes^60)/(1-des_mes),acum_c2,MIN('Parámetros'!$B$15,acum_c1*'Parámetros'!$B$16),sub_por_t,'Parámetros'!$B$12*'Parámetros'!$B$23*'Parámetros'!$B$21*'Parámetros'!$B$22*'Parámetros'!$B$24,cap_total,acum_c1+acum_c2,precio_adj,'Parámetros'!$B$10*(1+'Parámetros'!$B$13)^(60/12),terrenos_aprox,MAX(0,ENTERO(cap_total/precio_adj)),ENTERO((cap_total+terrenos_aprox*sub_por_t)/precio_adj)) | F10: =LET(des_mes,(1-'Parámetros'!$B$7)^(1/12),acum_c1,40000*1000*(1-des_mes^60)/(1-des_mes),acum_c2,MIN('Parámetros'!$B$15,acum_c1*'Parámetros'!$B$16),sub_por_t,'Parámetros'!$B$12*'Parámetros'!$B$23*'Parámetros'!$B$21*'Parámetros'!$B$22*'Parámetros'!$B$24,cap_total,acum_c1+acum_c2,precio_adj,'Parámetros'!$B$10*(1+'Parámetros'!$B$13)^(60/12),terrenos_aprox,MAX(0,ENTERO(cap_total/precio_adj)),ENTERO((cap_total+terrenos_aprox*sub_por_t)/precio_adj))
A13: TABLA 2 — Ratio Cobertura Deuda Capa 2 a 15 Años (Canon / Servicio Deuda)
A14: Ret.C2 \ Canon | B14: 15000 | C14: 20000 | D14: 25000 | E14: 30000 | F14: 35000
A15: 0.03 | B15: =LET(des_mes,(1-'Parámetros'!$B$7)^(1/12),acum_c1,'Parámetros'!$B$6*'Parámetros'!$B$5*(1-des_mes^180)/(1-des_mes),acum_c2,MIN('Parámetros'!$B$15,acum_c1*'Parámetros'!$B$16),sub_por_t,'Parámetros'!$B$12*'Parámetros'!$B$23*'Parámetros'!$B$21*'Parámetros'!$B$22*'Parámetros'!$B$24,cap_total,acum_c1+acum_c2,precio_adj,'Parámetros'!$B$10*(1+'Parámetros'!$B$13)^(180/12),terrenos,MAX(0,ENTERO(cap_total/precio_adj)),fam_ubic,terrenos*'Parámetros'!$B$12,canon_anual,fam_ubic*15000*(1+'Parámetros'!$B$27)^(180/12)*12,serv_deuda,acum_c2*0.03,IF(serv_deuda=0,999,REDONDEAR(canon_anual/serv_deuda,2))) | C15: =LET(des_mes,(1-'Parámetros'!$B$7)^(1/12),acum_c1,'Parámetros'!$B$6*'Parámetros'!$B$5*(1-des_mes^180)/(1-des_mes),acum_c2,MIN('Parámetros'!$B$15,acum_c1*'Parámetros'!$B$16),sub_por_t,'Parámetros'!$B$12*'Parámetros'!$B$23*'Parámetros'!$B$21*'Parámetros'!$B$22*'Parámetros'!$B$24,cap_total,acum_c1+acum_c2,precio_adj,'Parámetros'!$B$10*(1+'Parámetros'!$B$13)^(180/12),terrenos,MAX(0,ENTERO(cap_total/precio_adj)),fam_ubic,terrenos*'Parámetros'!$B$12,canon_anual,fam_ubic*20000*(1+'Parámetros'!$B$27)^(180/12)*12,serv_deuda,acum_c2*0.03,IF(serv_deuda=0,999,REDONDEAR(canon_anual/serv_deuda,2))) | D15: =LET(des_mes,(1-'Parámetros'!$B$7)^(1/12),acum_c1,'Parámetros'!$B$6*'Parámetros'!$B$5*(1-des_mes^180)/(1-des_mes),acum_c2,MIN('Parámetros'!$B$15,acum_c1*'Parámetros'!$B$16),sub_por_t,'Parámetros'!$B$12*'Parámetros'!$B$23*'Parámetros'!$B$21*'Parámetros'!$B$22*'Parámetros'!$B$24,cap_total,acum_c1+acum_c2,precio_adj,'Parámetros'!$B$10*(1+'Parámetros'!$B$13)^(180/12),terrenos,MAX(0,ENTERO(cap_total/precio_adj)),fam_ubic,terrenos*'Parámetros'!$B$12,canon_anual,fam_ubic*25000*(1+'Parámetros'!$B$27)^(180/12)*12,serv_deuda,acum_c2*0.03,IF(serv_deuda=0,999,REDONDEAR(canon_anual/serv_deuda,2))) | E15: =LET(des_mes,(1-'Parámetros'!$B$7)^(1/12),acum_c1,'Parámetros'!$B$6*'Parámetros'!$B$5*(1-des_mes^180)/(1-des_mes),acum_c2,MIN('Parámetros'!$B$15,acum_c1*'Parámetros'!$B$16),sub_por_t,'Parámetros'!$B$12*'Parámetros'!$B$23*'Parámetros'!$B$21*'Parámetros'!$B$22*'Parámetros'!$B$24,cap_total,acum_c1+acum_c2,precio_adj,'Parámetros'!$B$10*(1+'Parámetros'!$B$13)^(180/12),terrenos,MAX(0,ENTERO(cap_total/precio_adj)),fam_ubic,terrenos*'Parámetros'!$B$12,canon_anual,fam_ubic*30000*(1+'Parámetros'!$B$27)^(180/12)*12,serv_deuda,acum_c2*0.03,IF(serv_deuda=0,999,REDONDEAR(canon_anual/serv_deuda,2))) | F15: =LET(des_mes,(1-'Parámetros'!$B$7)^(1/12),acum_c1,'Parámetros'!$B$6*'Parámetros'!$B$5*(1-des_mes^180)/(1-des_mes),acum_c2,MIN('Parámetros'!$B$15,acum_c1*'Parámetros'!$B$16),sub_por_t,'Parámetros'!$B$12*'Parámetros'!$B$23*'Parámetros'!$B$21*'Parámetros'!$B$22*'Parámetros'!$B$24,cap_total,acum_c1+acum_c2,precio_adj,'Parámetros'!$B$10*(1+'Parámetros'!$B$13)^(180/12),terrenos,MAX(0,ENTERO(cap_total/precio_adj)),fam_ubic,terrenos*'Parámetros'!$B$12,canon_anual,fam_ubic*35000*(1+'Parámetros'!$B$27)^(180/12)*12,serv_deuda,acum_c2*0.03,IF(serv_deuda=0,999,REDONDEAR(canon_anual/serv_deuda,2)))
A16: 0.04 | B16: =LET(des_mes,(1-'Parámetros'!$B$7)^(1/12),acum_c1,'Parámetros'!$B$6*'Parámetros'!$B$5*(1-des_mes^180)/(1-des_mes),acum_c2,MIN('Parámetros'!$B$15,acum_c1*'Parámetros'!$B$16),sub_por_t,'Parámetros'!$B$12*'Parámetros'!$B$23*'Parámetros'!$B$21*'Parámetros'!$B$22*'Parámetros'!$B$24,cap_total,acum_c1+acum_c2,precio_adj,'Parámetros'!$B$10*(1+'Parámetros'!$B$13)^(180/12),terrenos,MAX(0,ENTERO(cap_total/precio_adj)),fam_ubic,terrenos*'Parámetros'!$B$12,canon_anual,fam_ubic*15000*(1+'Parámetros'!$B$27)^(180/12)*12,serv_deuda,acum_c2*0.04,IF(serv_deuda=0,999,REDONDEAR(canon_anual/serv_deuda,2))) | C16: =LET(des_mes,(1-'Parámetros'!$B$7)^(1/12),acum_c1,'Parámetros'!$B$6*'Parámetros'!$B$5*(1-des_mes^180)/(1-des_mes),acum_c2,MIN('Parámetros'!$B$15,acum_c1*'Parámetros'!$B$16),sub_por_t,'Parámetros'!$B$12*'Parámetros'!$B$23*'Parámetros'!$B$21*'Parámetros'!$B$22*'Parámetros'!$B$24,cap_total,acum_c1+acum_c2,precio_adj,'Parámetros'!$B$10*(1+'Parámetros'!$B$13)^(180/12),terrenos,MAX(0,ENTERO(cap_total/precio_adj)),fam_ubic,terrenos*'Parámetros'!$B$12,canon_anual,fam_ubic*20000*(1+'Parámetros'!$B$27)^(180/12)*12,serv_deuda,acum_c2*0.04,IF(serv_deuda=0,999,REDONDEAR(canon_anual/serv_deuda,2))) | D16: =LET(des_mes,(1-'Parámetros'!$B$7)^(1/12),acum_c1,'Parámetros'!$B$6*'Parámetros'!$B$5*(1-des_mes^180)/(1-des_mes),acum_c2,MIN('Parámetros'!$B$15,acum_c1*'Parámetros'!$B$16),sub_por_t,'Parámetros'!$B$12*'Parámetros'!$B$23*'Parámetros'!$B$21*'Parámetros'!$B$22*'Parámetros'!$B$24,cap_total,acum_c1+acum_c2,precio_adj,'Parámetros'!$B$10*(1+'Parámetros'!$B$13)^(180/12),terrenos,MAX(0,ENTERO(cap_total/precio_adj)),fam_ubic,terrenos*'Parámetros'!$B$12,canon_anual,fam_ubic*25000*(1+'Parámetros'!$B$27)^(180/12)*12,serv_deuda,acum_c2*0.04,IF(serv_deuda=0,999,REDONDEAR(canon_anual/serv_deuda,2))) | E16: =LET(des_mes,(1-'Parámetros'!$B$7)^(1/12),acum_c1,'Parámetros'!$B$6*'Parámetros'!$B$5*(1-des_mes^180)/(1-des_mes),acum_c2,MIN('Parámetros'!$B$15,acum_c1*'Parámetros'!$B$16),sub_por_t,'Parámetros'!$B$12*'Parámetros'!$B$23*'Parámetros'!$B$21*'Parámetros'!$B$22*'Parámetros'!$B$24,cap_total,acum_c1+acum_c2,precio_adj,'Parámetros'!$B$10*(1+'Parámetros'!$B$13)^(180/12),terrenos,MAX(0,ENTERO(cap_total/precio_adj)),fam_ubic,terrenos*'Parámetros'!$B$12,canon_anual,fam_ubic*30000*(1+'Parámetros'!$B$27)^(180/12)*12,serv_deuda,acum_c2*0.04,IF(serv_deuda=0,999,REDONDEAR(canon_anual/serv_deuda,2))) | F16: =LET(des_mes,(1-'Parámetros'!$B$7)^(1/12),acum_c1,'Parámetros'!$B$6*'Parámetros'!$B$5*(1-des_mes^180)/(1-des_mes),acum_c2,MIN('Parámetros'!$B$15,acum_c1*'Parámetros'!$B$16),sub_por_t,'Parámetros'!$B$12*'Parámetros'!$B$23*'Parámetros'!$B$21*'Parámetros'!$B$22*'Parámetros'!$B$24,cap_total,acum_c1+acum_c2,precio_adj,'Parámetros'!$B$10*(1+'Parámetros'!$B$13)^(180/12),terrenos,MAX(0,ENTERO(cap_total/precio_adj)),fam_ubic,terrenos*'Parámetros'!$B$12,canon_anual,fam_ubic*35000*(1+'Parámetros'!$B$27)^(180/12)*12,serv_deuda,acum_c2*0.04,IF(serv_deuda=0,999,REDONDEAR(canon_anual/serv_deuda,2)))
A17: 0.05 | B17: =LET(des_mes,(1-'Parámetros'!$B$7)^(1/12),acum_c1,'Parámetros'!$B$6*'Parámetros'!$B$5*(1-des_mes^180)/(1-des_mes),acum_c2,MIN('Parámetros'!$B$15,acum_c1*'Parámetros'!$B$16),sub_por_t,'Parámetros'!$B$12*'Parámetros'!$B$23*'Parámetros'!$B$21*'Parámetros'!$B$22*'Parámetros'!$B$24,cap_total,acum_c1+acum_c2,precio_adj,'Parámetros'!$B$10*(1+'Parámetros'!$B$13)^(180/12),terrenos,MAX(0,ENTERO(cap_total/precio_adj)),fam_ubic,terrenos*'Parámetros'!$B$12,canon_anual,fam_ubic*15000*(1+'Parámetros'!$B$27)^(180/12)*12,serv_deuda,acum_c2*0.05,IF(serv_deuda=0,999,REDONDEAR(canon_anual/serv_deuda,2))) | C17: =LET(des_mes,(1-'Parámetros'!$B$7)^(1/12),acum_c1,'Parámetros'!$B$6*'Parámetros'!$B$5*(1-des_mes^180)/(1-des_mes),acum_c2,MIN('Parámetros'!$B$15,acum_c1*'Parámetros'!$B$16),sub_por_t,'Parámetros'!$B$12*'Parámetros'!$B$23*'Parámetros'!$B$21*'Parámetros'!$B$22*'Parámetros'!$B$24,cap_total,acum_c1+acum_c2,precio_adj,'Parámetros'!$B$10*(1+'Parámetros'!$B$13)^(180/12),terrenos,MAX(0,ENTERO(cap_total/precio_adj)),fam_ubic,terrenos*'Parámetros'!$B$12,canon_anual,fam_ubic*20000*(1+'Parámetros'!$B$27)^(180/12)*12,serv_deuda,acum_c2*0.05,IF(serv_deuda=0,999,REDONDEAR(canon_anual/serv_deuda,2))) | D17: =LET(des_mes,(1-'Parámetros'!$B$7)^(1/12),acum_c1,'Parámetros'!$B$6*'Parámetros'!$B$5*(1-des_mes^180)/(1-des_mes),acum_c2,MIN('Parámetros'!$B$15,acum_c1*'Parámetros'!$B$16),sub_por_t,'Parámetros'!$B$12*'Parámetros'!$B$23*'Parámetros'!$B$21*'Parámetros'!$B$22*'Parámetros'!$B$24,cap_total,acum_c1+acum_c2,precio_adj,'Parámetros'!$B$10*(1+'Parámetros'!$B$13)^(180/12),terrenos,MAX(0,ENTERO(cap_total/precio_adj)),fam_ubic,terrenos*'Parámetros'!$B$12,canon_anual,fam_ubic*25000*(1+'Parámetros'!$B$27)^(180/12)*12,serv_deuda,acum_c2*0.05,IF(serv_deuda=0,999,REDONDEAR(canon_anual/serv_deuda,2))) | E17: =LET(des_mes,(1-'Parámetros'!$B$7)^(1/12),acum_c1,'Parámetros'!$B$6*'Parámetros'!$B$5*(1-des_mes^180)/(1-des_mes),acum_c2,MIN('Parámetros'!$B$15,acum_c1*'Parámetros'!$B$16),sub_por_t,'Parámetros'!$B$12*'Parámetros'!$B$23*'Parámetros'!$B$21*'Parámetros'!$B$22*'Parámetros'!$B$24,cap_total,acum_c1+acum_c2,precio_adj,'Parámetros'!$B$10*(1+'Parámetros'!$B$13)^(180/12),terrenos,MAX(0,ENTERO(cap_total/precio_adj)),fam_ubic,terrenos*'Parámetros'!$B$12,canon_anual,fam_ubic*30000*(1+'Parámetros'!$B$27)^(180/12)*12,serv_deuda,acum_c2*0.05,IF(serv_deuda=0,999,REDONDEAR(canon_anual/serv_deuda,2))) | F17: =LET(des_mes,(1-'Parámetros'!$B$7)^(1/12),acum_c1,'Parámetros'!$B$6*'Parámetros'!$B$5*(1-des_mes^180)/(1-des_mes),acum_c2,MIN('Parámetros'!$B$15,acum_c1*'Parámetros'!$B$16),sub_por_t,'Parámetros'!$B$12*'Parámetros'!$B$23*'Parámetros'!$B$21*'Parámetros'!$B$22*'Parámetros'!$B$24,cap_total,acum_c1+acum_c2,precio_adj,'Parámetros'!$B$10*(1+'Parámetros'!$B$13)^(180/12),terrenos,MAX(0,ENTERO(cap_total/precio_adj)),fam_ubic,terrenos*'Parámetros'!$B$12,canon_anual,fam_ubic*35000*(1+'Parámetros'!$B$27)^(180/12)*12,serv_deuda,acum_c2*0.05,IF(serv_deuda=0,999,REDONDEAR(canon_anual/serv_deuda,2)))
A18: 0.06 | B18: =LET(des_mes,(1-'Parámetros'!$B$7)^(1/12),acum_c1,'Parámetros'!$B$6*'Parámetros'!$B$5*(1-des_mes^180)/(1-des_mes),acum_c2,MIN('Parámetros'!$B$15,acum_c1*'Parámetros'!$B$16),sub_por_t,'Parámetros'!$B$12*'Parámetros'!$B$23*'Parámetros'!$B$21*'Parámetros'!$B$22*'Parámetros'!$B$24,cap_total,acum_c1+acum_c2,precio_adj,'Parámetros'!$B$10*(1+'Parámetros'!$B$13)^(180/12),terrenos,MAX(0,ENTERO(cap_total/precio_adj)),fam_ubic,terrenos*'Parámetros'!$B$12,canon_anual,fam_ubic*15000*(1+'Parámetros'!$B$27)^(180/12)*12,serv_deuda,acum_c2*0.06,IF(serv_deuda=0,999,REDONDEAR(canon_anual/serv_deuda,2))) | C18: =LET(des_mes,(1-'Parámetros'!$B$7)^(1/12),acum_c1,'Parámetros'!$B$6*'Parámetros'!$B$5*(1-des_mes^180)/(1-des_mes),acum_c2,MIN('Parámetros'!$B$15,acum_c1*'Parámetros'!$B$16),sub_por_t,'Parámetros'!$B$12*'Parámetros'!$B$23*'Parámetros'!$B$21*'Parámetros'!$B$22*'Parámetros'!$B$24,cap_total,acum_c1+acum_c2,precio_adj,'Parámetros'!$B$10*(1+'Parámetros'!$B$13)^(180/12),terrenos,MAX(0,ENTERO(cap_total/precio_adj)),fam_ubic,terrenos*'Parámetros'!$B$12,canon_anual,fam_ubic*20000*(1+'Parámetros'!$B$27)^(180/12)*12,serv_deuda,acum_c2*0.06,IF(serv_deuda=0,999,REDONDEAR(canon_anual/serv_deuda,2))) | D18: =LET(des_mes,(1-'Parámetros'!$B$7)^(1/12),acum_c1,'Parámetros'!$B$6*'Parámetros'!$B$5*(1-des_mes^180)/(1-des_mes),acum_c2,MIN('Parámetros'!$B$15,acum_c1*'Parámetros'!$B$16),sub_por_t,'Parámetros'!$B$12*'Parámetros'!$B$23*'Parámetros'!$B$21*'Parámetros'!$B$22*'Parámetros'!$B$24,cap_total,acum_c1+acum_c2,precio_adj,'Parámetros'!$B$10*(1+'Parámetros'!$B$13)^(180/12),terrenos,MAX(0,ENTERO(cap_total/precio_adj)),fam_ubic,terrenos*'Parámetros'!$B$12,canon_anual,fam_ubic*25000*(1+'Parámetros'!$B$27)^(180/12)*12,serv_deuda,acum_c2*0.06,IF(serv_deuda=0,999,REDONDEAR(canon_anual/serv_deuda,2))) | E18: =LET(des_mes,(1-'Parámetros'!$B$7)^(1/12),acum_c1,'Parámetros'!$B$6*'Parámetros'!$B$5*(1-des_mes^180)/(1-des_mes),acum_c2,MIN('Parámetros'!$B$15,acum_c1*'Parámetros'!$B$16),sub_por_t,'Parámetros'!$B$12*'Parámetros'!$B$23*'Parámetros'!$B$21*'Parámetros'!$B$22*'Parámetros'!$B$24,cap_total,acum_c1+acum_c2,precio_adj,'Parámetros'!$B$10*(1+'Parámetros'!$B$13)^(180/12),terrenos,MAX(0,ENTERO(cap_total/precio_adj)),fam_ubic,terrenos*'Parámetros'!$B$12,canon_anual,fam_ubic*30000*(1+'Parámetros'!$B$27)^(180/12)*12,serv_deuda,acum_c2*0.06,IF(serv_deuda=0,999,REDONDEAR(canon_anual/serv_deuda,2))) | F18: =LET(des_mes,(1-'Parámetros'!$B$7)^(1/12),acum_c1,'Parámetros'!$B$6*'Parámetros'!$B$5*(1-des_mes^180)/(1-des_mes),acum_c2,MIN('Parámetros'!$B$15,acum_c1*'Parámetros'!$B$16),sub_por_t,'Parámetros'!$B$12*'Parámetros'!$B$23*'Parámetros'!$B$21*'Parámetros'!$B$22*'Parámetros'!$B$24,cap_total,acum_c1+acum_c2,precio_adj,'Parámetros'!$B$10*(1+'Parámetros'!$B$13)^(180/12),terrenos,MAX(0,ENTERO(cap_total/precio_adj)),fam_ubic,terrenos*'Parámetros'!$B$12,canon_anual,fam_ubic*35000*(1+'Parámetros'!$B$27)^(180/12)*12,serv_deuda,acum_c2*0.06,IF(serv_deuda=0,999,REDONDEAR(canon_anual/serv_deuda,2)))
A19: 0.07 | B19: =LET(des_mes,(1-'Parámetros'!$B$7)^(1/12),acum_c1,'Parámetros'!$B$6*'Parámetros'!$B$5*(1-des_mes^180)/(1-des_mes),acum_c2,MIN('Parámetros'!$B$15,acum_c1*'Parámetros'!$B$16),sub_por_t,'Parámetros'!$B$12*'Parámetros'!$B$23*'Parámetros'!$B$21*'Parámetros'!$B$22*'Parámetros'!$B$24,cap_total,acum_c1+acum_c2,precio_adj,'Parámetros'!$B$10*(1+'Parámetros'!$B$13)^(180/12),terrenos,MAX(0,ENTERO(cap_total/precio_adj)),fam_ubic,terrenos*'Parámetros'!$B$12,canon_anual,fam_ubic*15000*(1+'Parámetros'!$B$27)^(180/12)*12,serv_deuda,acum_c2*0.07,IF(serv_deuda=0,999,REDONDEAR(canon_anual/serv_deuda,2))) | C19: =LET(des_mes,(1-'Parámetros'!$B$7)^(1/12),acum_c1,'Parámetros'!$B$6*'Parámetros'!$B$5*(1-des_mes^180)/(1-des_mes),acum_c2,MIN('Parámetros'!$B$15,acum_c1*'Parámetros'!$B$16),sub_por_t,'Parámetros'!$B$12*'Parámetros'!$B$23*'Parámetros'!$B$21*'Parámetros'!$B$22*'Parámetros'!$B$24,cap_total,acum_c1+acum_c2,precio_adj,'Parámetros'!$B$10*(1+'Parámetros'!$B$13)^(180/12),terrenos,MAX(0,ENTERO(cap_total/precio_adj)),fam_ubic,terrenos*'Parámetros'!$B$12,canon_anual,fam_ubic*20000*(1+'Parámetros'!$B$27)^(180/12)*12,serv_deuda,acum_c2*0.07,IF(serv_deuda=0,999,REDONDEAR(canon_anual/serv_deuda,2))) | D19: =LET(des_mes,(1-'Parámetros'!$B$7)^(1/12),acum_c1,'Parámetros'!$B$6*'Parámetros'!$B$5*(1-des_mes^180)/(1-des_mes),acum_c2,MIN('Parámetros'!$B$15,acum_c1*'Parámetros'!$B$16),sub_por_t,'Parámetros'!$B$12*'Parámetros'!$B$23*'Parámetros'!$B$21*'Parámetros'!$B$22*'Parámetros'!$B$24,cap_total,acum_c1+acum_c2,precio_adj,'Parámetros'!$B$10*(1+'Parámetros'!$B$13)^(180/12),terrenos,MAX(0,ENTERO(cap_total/precio_adj)),fam_ubic,terrenos*'Parámetros'!$B$12,canon_anual,fam_ubic*25000*(1+'Parámetros'!$B$27)^(180/12)*12,serv_deuda,acum_c2*0.07,IF(serv_deuda=0,999,REDONDEAR(canon_anual/serv_deuda,2))) | E19: =LET(des_mes,(1-'Parámetros'!$B$7)^(1/12),acum_c1,'Parámetros'!$B$6*'Parámetros'!$B$5*(1-des_mes^180)/(1-des_mes),acum_c2,MIN('Parámetros'!$B$15,acum_c1*'Parámetros'!$B$16),sub_por_t,'Parámetros'!$B$12*'Parámetros'!$B$23*'Parámetros'!$B$21*'Parámetros'!$B$22*'Parámetros'!$B$24,cap_total,acum_c1+acum_c2,precio_adj,'Parámetros'!$B$10*(1+'Parámetros'!$B$13)^(180/12),terrenos,MAX(0,ENTERO(cap_total/precio_adj)),fam_ubic,terrenos*'Parámetros'!$B$12,canon_anual,fam_ubic*30000*(1+'Parámetros'!$B$27)^(180/12)*12,serv_deuda,acum_c2*0.07,IF(serv_deuda=0,999,REDONDEAR(canon_anual/serv_deuda,2))) | F19: =LET(des_mes,(1-'Parámetros'!$B$7)^(1/12),acum_c1,'Parámetros'!$B$6*'Parámetros'!$B$5*(1-des_mes^180)/(1-des_mes),acum_c2,MIN('Parámetros'!$B$15,acum_c1*'Parámetros'!$B$16),sub_por_t,'Parámetros'!$B$12*'Parámetros'!$B$23*'Parámetros'!$B$21*'Parámetros'!$B$22*'Parámetros'!$B$24,cap_total,acum_c1+acum_c2,precio_adj,'Parámetros'!$B$10*(1+'Parámetros'!$B$13)^(180/12),terrenos,MAX(0,ENTERO(cap_total/precio_adj)),fam_ubic,terrenos*'Parámetros'!$B$12,canon_anual,fam_ubic*35000*(1+'Parámetros'!$B$27)^(180/12)*12,serv_deuda,acum_c2*0.07,IF(serv_deuda=0,999,REDONDEAR(canon_anual/serv_deuda,2)))
A27: TABLA 3 — Meses Hasta Primer Sorteo (primer terreno adquirido)
A28: Familias \ Precio | B28: 80000000 | C28: 100000000 | D28: 120000000 | E28: 150000000 | F28: 200000000
A29: 100 | B29: =LET(des_mes,(1-'Parámetros'!$B$7)^(1/12),meses,SECUENCIA(180),acum_c1,'Parámetros'!$B$6*100*(1-des_mes^meses)/(1-des_mes),acum_c2,MIN('Parámetros'!$B$15,acum_c1*'Parámetros'!$B$16),cap_total,acum_c1+acum_c2,precio_adj,80000000*(1+'Parámetros'!$B$13)^((meses-1)/12),puede,cap_total>=precio_adj,idx,COINCIDIR(VERDADERO,puede,0),IF(ESERROR(idx),">180",idx)) | C29: =LET(des_mes,(1-'Parámetros'!$B$7)^(1/12),meses,SECUENCIA(180),acum_c1,'Parámetros'!$B$6*100*(1-des_mes^meses)/(1-des_mes),acum_c2,MIN('Parámetros'!$B$15,acum_c1*'Parámetros'!$B$16),cap_total,acum_c1+acum_c2,precio_adj,100000000*(1+'Parámetros'!$B$13)^((meses-1)/12),puede,cap_total>=precio_adj,idx,COINCIDIR(VERDADERO,puede,0),IF(ESERROR(idx),">180",idx)) | D29: =LET(des_mes,(1-'Parámetros'!$B$7)^(1/12),meses,SECUENCIA(180),acum_c1,'Parámetros'!$B$6*100*(1-des_mes^meses)/(1-des_mes),acum_c2,MIN('Parámetros'!$B$15,acum_c1*'Parámetros'!$B$16),cap_total,acum_c1+acum_c2,precio_adj,120000000*(1+'Parámetros'!$B$13)^((meses-1)/12),puede,cap_total>=precio_adj,idx,COINCIDIR(VERDADERO,puede,0),IF(ESERROR(idx),">180",idx)) | E29: =LET(des_mes,(1-'Parámetros'!$B$7)^(1/12),meses,SECUENCIA(180),acum_c1,'Parámetros'!$B$6*100*(1-des_mes^meses)/(1-des_mes),acum_c2,MIN('Parámetros'!$B$15,acum_c1*'Parámetros'!$B$16),cap_total,acum_c1+acum_c2,precio_adj,150000000*(1+'Parámetros'!$B$13)^((meses-1)/12),puede,cap_total>=precio_adj,idx,COINCIDIR(VERDADERO,puede,0),IF(ESERROR(idx),">180",idx)) | F29: =LET(des_mes,(1-'Parámetros'!$B$7)^(1/12),meses,SECUENCIA(180),acum_c1,'Parámetros'!$B$6*100*(1-des_mes^meses)/(1-des_mes),acum_c2,MIN('Parámetros'!$B$15,acum_c1*'Parámetros'!$B$16),cap_total,acum_c1+acum_c2,precio_adj,200000000*(1+'Parámetros'!$B$13)^((meses-1)/12),puede,cap_total>=precio_adj,idx,COINCIDIR(VERDADERO,puede,0),IF(ESERROR(idx),">180",idx))
